Workbook

Sheet OJC
A1: 광케이블 선번장
A3: 선로ID | B3: 605791445 | D3: 선로명 | N3: (철거예정)(기간망추가수용금지)B00-03 MD1~24(FC) | O3: 규격 | P3: 288C | S3: N/W구분 | T3: 혼합선로
A4: 시점 | B4: 8720H253 | O4: LOT No. | P4: 6178 | S4: 자산번호
A5: 종점 | B5: 인천간석사옥/인천종합국사(1층) | O5: 자재코드 | P5: 530058 | S5: 자재명 | T5: 광케이블,288C,가공
L6: 랙#B5-09_
A7: UNIT | B7: 선번 | C7: 구성상태 | D7: 코어ID | E7: 선번 | F7: 44-144 | G7: 44-288 | H7: 44-288-1 | I7: 46-288 | J7: 46-288-1 | K7: 115-144 | L7: MD선번 | M7: ofd선번 | N7: 코어명 | O7: 광선로감시여부 | P7: 장비OJC타입 | Q7: OJC(M) | R7: 장비 랙 | S7: 장비 | T7: 코어수용서비스상세 | U7: 수용서비스범위 | V7: 영향고객수 | W7: 연계회선번호 | X7: 가입자번호 | Y7: 단선(불량)여부 | Z7: 직결공사번호 | AA7: Network명 | AB7: Network ID | AC7: 상위국설치장소명 | AD7: 상위국장비모델 | AE7: 상위국장비명 | AF7: 상위국TID | AG7: 상위국AID(port) | AH7: 하위국설치장소명 | AI7: 하위국장비모델 | AJ7: 하위국장비명 | AK7: 하위국TID | AL7: 하위국AID(port)
A8: Unit#1 | F8: =IF(D8="(연결)","",VLOOKUP(D8,'44-144'!D:E,2,0)) | G8: =IF(D8="(연결)","",VLOOKUP(D8,'44-288'!D:E,2,0)) | H8: =IF(D8="(연결)","",VLOOKUP(D8,'44-288-1'!D:E,2,0)) | I8: =IF(D8="(연결)","",VLOOKUP(D8,'46-288'!D:E,2,0)) | J8: =IF(D8="(연결)","",VLOOKUP(D8,'46-288-1'!D:E,2,0)) | K8: =IF(D8="(연결)","",VLOOKUP(D8,'115-144'!D:E,2,0))
A9: 1 | B9: 1 | C9: 운영중(OK) | D9: 7053387 | E9: 1 | F9: =IF(D9="(연결)","",VLOOKUP(D9,'44-144'!D:E,2,0)) -> #N/A | G9: =IF(D9="(연결)","",VLOOKUP(D9,'44-288'!D:E,2,0)) -> #N/A | H9: =IF(D9="(연결)","",VLOOKUP(D9,'44-288-1'!D:E,2,0)) -> #N/A | I9: =IF(D9="(연결)","",VLOOKUP(D9,'46-288'!D:E,2,0)) -> #N/A | J9: =IF(D9="(연결)","",VLOOKUP(D9,'46-288-1'!D:E,2,0)) -> #N/A | K9: =IF(D9="(연결)","",VLOOKUP(D9,'115-144'!D:E,2,0)) -> 1 | L9: MD1-1 | M9: 1 | N9: 인천간석사옥/인천종합국사(1층)~인천종합국사_102093/102103_1_0_0_8821R052_2:8RN [인천종합국사_102103_1_0_0_8821R052_2:8RN] | O9: N | P9: LC/PC-SC/PC | Q9: 25 | R9: B2-1 | S9: V8500#2 | T9: FTTH 1차 RN | U9: 140810396 | V9: 4 | AC9: 인천간석사옥/인천종합국사(1층) | AD9: V8500 | AE9: H_TONGHAB-V8500-2-TPS | AF9: TONGHAB-V8500-2-TPS | AG9: 3 | AH9: 인천종합국사_102093/102103_1_0_0_8821R052_2:8RN | AI9: RN 2:8 | AJ9: 구월25셀_2:8RN_8821R052(가공형간석동1_210)_종합V5724#7_920 | AK9: 인천간석_207092/207102_1_0_0_8821R052(가공형간석동1_210)RN 2:8 | AL9: I_P1
A10: 1 | B10: 2 | C10: 운영중(OK) | D10: 7053386 | E10: 2 | F10: =IF(D10="(연결)","",VLOOKUP(D10,'44-144'!D:E,2,0)) -> #N/A | G10: =IF(D10="(연결)","",VLOOKUP(D10,'44-288'!D:E,2,0)) -> #N/A | H10: =IF(D10="(연결)","",VLOOKUP(D10,'44-288-1'!D:E,2,0)) -> #N/A | I10: =IF(D10="(연결)","",VLOOKUP(D10,'46-288'!D:E,2,0)) -> #N/A | J10: =IF(D10="(연결)","",VLOOKUP(D10,'46-288-1'!D:E,2,0)) -> #N/A | K10: =IF(D10="(연결)","",VLOOKUP(D10,'115-144'!D:E,2,0)) -> 2 | L10: MD1-2 | M10: 2 | N10: 인천간석사옥/인천종합국사(1층)~인천종합국사_111094/111104_1_0_0[8721X312] 2:8RN [인천종합국사_111104_1_0_0[8721X312] 2:8RN] | O10: N | P10: LC/PC-SC/PC | Q10: 25 | R10: B2-1 | S10: V8500#11 | T10: FTTH 1차 RN | U10: 201044967 | V10: 2 | AC10: 인천간석사옥/인천종합국사(1층) | AD10: V8500 | AE10: H_JongHab-V8500-11-SME | AF10: H_JongHab-V8500-11-SME | AG10: 4 | AH10: 인천종합국사_111094/111104_1_0_0[8721X312] 2:8RN | AI10: RN 2:8 | AJ10: 인천종합 GS/B8-02-1[8721X312] | AK10: 인천간석_208011/208021_1_0_0[8721X312] 2:8RN | AL10: I_P2
A11: 1 | B11: 3 | C11: (해지)운영중(OK) | D11: 7053389 | E11: 3 | F11: =IF(D11="(연결)","",VLOOKUP(D11,'44-144'!D:E,2,0)) -> #N/A | G11: =IF(D11="(연결)","",VLOOKUP(D11,'44-288'!D:E,2,0)) -> #N/A | H11: =IF(D11="(연결)","",VLOOKUP(D11,'44-288-1'!D:E,2,0)) -> #N/A | I11: =IF(D11="(연결)","",VLOOKUP(D11,'46-288'!D:E,2,0)) -> #N/A | J11: =IF(D11="(연결)","",VLOOKUP(D11,'46-288-1'!D:E,2,0)) -> #N/A | K11: =IF(D11="(연결)","",VLOOKUP(D11,'115-144'!D:E,2,0)) -> 3 | L11: - | N11: 인천간석사옥/인천종합국사(1층)~인천종합 GS/B?-??-1[8820A081] [인천종합 만수 MS/B?-??-1[8820A081]] | O11: N | Q11: 해지 | R11: 해지 | S11: 해지 | T11: FTTH 1차 RN | AC11: 인천간석사옥/인천종합국사(1층) | AH11: 인천종합 GS/B?-??-1[8820A081]
A12: 1 | B12: 4 | C12: 운영중(OK) | D12: 9842945 | E12: 4 | F12: =IF(D12="(연결)","",VLOOKUP(D12,'44-144'!D:E,2,0)) -> #N/A | G12: =IF(D12="(연결)","",VLOOKUP(D12,'44-288'!D:E,2,0)) -> 205 | H12: =IF(D12="(연결)","",VLOOKUP(D12,'44-288-1'!D:E,2,0)) -> #N/A | I12: =IF(D12="(연결)","",VLOOKUP(D12,'46-288'!D:E,2,0)) -> #N/A | J12: =IF(D12="(연결)","",VLOOKUP(D12,'46-288-1'!D:E,2,0)) -> #N/A | K12: =IF(D12="(연결)","",VLOOKUP(D12,'115-144'!D:E,2,0)) -> #N/A | L12: MD11-1 | M12: 241 | N12: 인천간석사옥/인천종합국사(1층)~500087838775_인천지하철2호선_모래내시장역/[중]남동구청역 지하2층 본선 [HLB_인천간석C3_3330A_만수_터_인천2호선(1500062728.1600209028.1500062761)] | O12: N | P12: LC/PC-LC/PC | Q12: 30 | R12: 4G DU C | S12: HLB_인천간석C3_3330A | T12: 기타 | AC12: 인천간석사옥/인천종합국사(1층) | AH12: 500087838775_인천지하철2호선_모래내시장역/[중]남동구청역 지하2층 본선
A13: 1 | B13: 5 | C13: 운영중(OK) | D13: 9842947 | E13: 5 | F13: =IF(D13="(연결)","",VLOOKUP(D13,'44-144'!D:E,2,0)) -> #N/A | G13: =IF(D13="(연결)","",VLOOKUP(D13,'44-288'!D:E,2,0)) -> 206 | H13: =IF(D13="(연결)","",VLOOKUP(D13,'44-288-1'!D:E,2,0)) -> #N/A | I13: =IF(D13="(연결)","",VLOOKUP(D13,'46-288'!D:E,2,0)) -> #N/A | J13: =IF(D13="(연결)","",VLOOKUP(D13,'46-288-1'!D:E,2,0)) -> #N/A | K13: =IF(D13="(연결)","",VLOOKUP(D13,'115-144'!D:E,2,0)) -> #N/A | L13: MD11-2 | M13: 242 | N13: 인천간석사옥/인천종합국사(1층)~500087838775_인천지하철2호선_모래내시장역/[중]남동구청역 지하2층 본선 [HLB_인천간석C3_3320A_만수_터_인천2호선(1500062727.1600209027.1500062760)] | O13: N | P13: LC/PC-LC/PC | Q13: 30 | R13: 4G DU C | S13: HLB_인천간석C3_3320A | T13: 기타 | AC13: 인천간석사옥/인천종합국사(1층) | AH13: 500087838775_인천지하철2호선_모래내시장역/[중]남동구청역 지하2층 본선
A14: 1 | B14: 6 | C14: 운영중(OK) | D14: 9842951 | E14: 6 | F14: =IF(D14="(연결)","",VLOOKUP(D14,'44-144'!D:E,2,0)) -> #N/A | G14: =IF(D14="(연결)","",VLOOKUP(D14,'44-288'!D:E,2,0)) -> 207 | H14: =IF(D14="(연결)","",VLOOKUP(D14,'44-288-1'!D:E,2,0)) -> #N/A | I14: =IF(D14="(연결)","",VLOOKUP(D14,'46-288'!D:E,2,0)) -> #N/A | J14: =IF(D14="(연결)","",VLOOKUP(D14,'46-288-1'!D:E,2,0)) -> #N/A | K14: =IF(D14="(연결)","",VLOOKUP(D14,'115-144'!D:E,2,0)) -> #N/A | L14: MD11-3 | M14: 243 | N14: 인천간석사옥/인천종합국사(1층)~500087838775_인천지하철2호선_모래내시장역/[중]남동구청역 지하2층 본선 [HLB_인천간석C3_3450A_만수_터_인천2호선(1500062730.1600209030.1500062763)] | O14: N | P14: LC/PC-LC/PC | Q14: 30 | R14: 4G DU C | S14: HLB_인천간석C3_3450A | T14: 기타 | AC14: 인천간석사옥/인천종합국사(1층) | AH14: 500087838775_인천지하철2호선_모래내시장역/[중]남동구청역 지하2층 본선
A15: 1 | B15: 7 | C15: 운영중(OK) | D15: 9842954 | E15: 7 | F15: =IF(D15="(연결)","",VLOOKUP(D15,'44-144'!D:E,2,0)) -> #N/A | G15: =IF(D15="(연결)","",VLOOKUP(D15,'44-288'!D:E,2,0)) -> 208 | H15: =IF(D15="(연결)","",VLOOKUP(D15,'44-288-1'!D:E,2,0)) -> #N/A | I15: =IF(D15="(연결)","",VLOOKUP(D15,'46-288'!D:E,2,0)) -> #N/A | J15: =IF(D15="(연결)","",VLOOKUP(D15,'46-288-1'!D:E,2,0)) -> #N/A | K15: =IF(D15="(연결)","",VLOOKUP(D15,'115-144'!D:E,2,0)) -> #N/A | L15: MD11-4 | M15: 244 | N15: 인천간석사옥/인천종합국사(1층)~500087838775_인천지하철2호선_모래내시장역/[중]남동구청역 지하2층 본선 [HLB_인천간석C3_3440A_만수_터_인천2호선(1500062729.1600209029.1500062762)] | O15: N | P15: LC/PC-LC/PC | Q15: 30 | R15: 4G DU C | S15: HLB_인천간석C3_3440A | T15: 기타 | AC15: 인천간석사옥/인천종합국사(1층) | AH15: 500087838775_인천지하철2호선_모래내시장역/[중]남동구청역 지하2층 본선
A16: 1 | B16: 8 | D16: (연결) | E16: 8 | F16: =IF(D16="(연결)","",VLOOKUP(D16,'44-144'!D:E,2,0)) | G16: =IF(D16="(연결)","",VLOOKUP(D16,'44-288'!D:E,2,0)) | H16: =IF(D16="(연결)","",VLOOKUP(D16,'44-288-1'!D:E,2,0)) | I16: =IF(D16="(연결)","",VLOOKUP(D16,'46-288'!D:E,2,0)) | J16: =IF(D16="(연결)","",VLOOKUP(D16,'46-288-1'!D:E,2,0)) | K16: =IF(D16="(연결)","",VLOOKUP(D16,'115-144'!D:E,2,0)) | N16: 인천종합국사(1층)(북인천분배센터)(뱅크)~[중접완료]8820A631#1 | O16: N
A17: 1 | B17: 9 | C17: 운영중(OK) | D17: 3060843859 | E17: 9 | F17: =IF(D17="(연결)","",VLOOKUP(D17,'44-144'!D:E,2,0)) -> #N/A | G17: =IF(D17="(연결)","",VLOOKUP(D17,'44-288'!D:E,2,0)) -> #N/A | H17: =IF(D17="(연결)","",VLOOKUP(D17,'44-288-1'!D:E,2,0)) -> #N/A | I17: =IF(D17="(연결)","",VLOOKUP(D17,'46-288'!D:E,2,0)) -> #N/A | J17: =IF(D17="(연결)","",VLOOKUP(D17,'46-288-1'!D:E,2,0)) -> #N/A | K17: =IF(D17="(연결)","",VLOOKUP(D17,'115-144'!D:E,2,0)) -> #N/A | N17: 인천간석사옥/인천종합국사(2층) [INIH]~간석동 우리은행(만수동지점)_500009389712/500208245586/500204869797_만수동금융센터 [간석동 우리은행(만수동지점)_500009389712/500208245586_만수동금융센터_B향] | O17: N | P17: LC/PC-FC/APC | Q17: 30 | R17: B8-7 | S17: UTRANS-1664_STM1U-16P/Port-P11 | T17: 기타 | AC17: 인천간석사옥/인천종합국사(2층) [INIH] | AD17: UTRANS-1664 | AF17: 우리은행 집선#1 | AG17: P11 | AH17: 간석동 우리은행(만수동지점)_500009389712/500208245586/500204869797_만수동금융센터 | AI17: 1646SMC(AC) | AJ17: 5WRB-ManSuDongGYC | AK17: 우리은행_만수동금융센터 | AL17: P2
A18: 1 | B18: 10 | C18: 운영중(OK) | D18: 3060843860 | E18: 10 | F18: =IF(D18="(연결)","",VLOOKUP(D18,'44-144'!D:E,2,0)) -> #N/A | G18: =IF(D18="(연결)","",VLOOKUP(D18,'44-288'!D:E,2,0)) -> #N/A | H18: =IF(D18="(연결)","",VLOOKUP(D18,'44-288-1'!D:E,2,0)) -> #N/A | I18: =IF(D18="(연결)","",VLOOKUP(D18,'46-288'!D:E,2,0)) -> #N/A | J18: =IF(D18="(연결)","",VLOOKUP(D18,'46-288-1'!D:E,2,0)) -> #N/A | K18: =IF(D18="(연결)","",VLOOKUP(D18,'115-144'!D:E,2,0)) -> #N/A | N18: 인천간석사옥/인천종합국사(2층) [INIH]~간석동 우리은행(만수동지점)_500009389712/500208245586/500204869797_만수동금융센터 [간석동 우리은행(만수동지점)_500009389712/500208245586_만수동금융센터_B향] | O18: N | P18: LC/PC-FC/APC | Q18: 30 | R18: B8-7 | S18: UTRANS-1664_STM1U-16P/Port-P11 | T18: 기타 | AC18: 인천간석사옥/인천종합국사(2층) [INIH] | AD18: UTRANS-1664 | AF18: 우리은행 집선#1 | AG18: P11 | AH18: 간석동 우리은행(만수동지점)_500009389712/500208245586/500204869797_만수동금융센터 | AI18: 1646SMC(AC) | AJ18: 5WRB-ManSuDongGYC | AK18: 우리은행_만수동금융센터 | AL18: P2
A19: 1 | B19: 11 | C19: 운영중(OK) | D19: 9842955 | E19: 11 | F19: =IF(D19="(연결)","",VLOOKUP(D19,'44-144'!D:E,2,0)) -> #N/A | G19: =IF(D19="(연결)","",VLOOKUP(D19,'44-288'!D:E,2,0)) -> 209 | H19: =IF(D19="(연결)","",VLOOKUP(D19,'44-288-1'!D:E,2,0)) -> #N/A | I19: =IF(D19="(연결)","",VLOOKUP(D19,'46-288'!D:E,2,0)) -> #N/A | J19: =IF(D19="(연결)","",VLOOKUP(D19,'46-288-1'!D:E,2,0)) -> #N/A | K19: =IF(D19="(연결)","",VLOOKUP(D19,'115-144'!D:E,2,0)) -> #N/A | L19: MD11-5 | M19: 245 | N19: 인천간석사옥/인천종합국사(1층)~500087838775_인천지하철2호선_모래내시장역/[중]남동구청역 지하2층 본선 [HLB_인천간석C4_3210A_남동구청_터_인천2호선(1500062732.1600209032.1500062765)] | O19: N | P19: LC/PC-LC/PC | Q19: 30 | R19: 4G DU C | S19: HLB_인천간석C4_3210A | T19: 기타 | AC19: 인천간석사옥/인천종합국사(1층) | AH19: 500087838775_인천지하철2호선_모래내시장역/[중]남동구청역 지하2층 본선
A20: 1 | B20: 12 | C20: 운영중(OK) | D20: 9842956 | E20: 12 | F20: =IF(D20="(연결)","",VLOOKUP(D20,'44-144'!D:E,2,0)) -> #N/A | G20: =IF(D20="(연결)","",VLOOKUP(D20,'44-288'!D:E,2,0)) -> 210 | H20: =IF(D20="(연결)","",VLOOKUP(D20,'44-288-1'!D:E,2,0)) -> #N/A | I20: =IF(D20="(연결)","",VLOOKUP(D20,'46-288'!D:E,2,0)) -> #N/A | J20: =IF(D20="(연결)","",VLOOKUP(D20,'46-288-1'!D:E,2,0)) -> #N/A | K20: =IF(D20="(연결)","",VLOOKUP(D20,'115-144'!D:E,2,0)) -> #N/A | L20: MD11-6 | M20: 246 | N20: 인천간석사옥/인천종합국사(1층)~500087838775_인천지하철2호선_모래내시장역/[중]남동구청역 지하2층 본선 [HLB_인천간석C4_3200A_남동구청_터_인천2호선(1500062711.1600209033.1500062764)] | O20: N | P20: LC/PC-LC/PC | Q20: 30 | R20: 4G DU C | S20: HLB_인천간석C4_3200A | T20: 기타 | AC20: 인천간석사옥/인천종합국사(1층) | AH20: 500087838775_인천지하철2호선_모래내시장역/[중]남동구청역 지하2층 본선
A21: Unit#2 | F21: =IF(D21="(연결)","",VLOOKUP(D21,'44-144'!D:E,2,0)) | G21: =IF(D21="(연결)","",VLOOKUP(D21,'44-288'!D:E,2,0)) | H21: =IF(D21="(연결)","",VLOOKUP(D21,'44-288-1'!D:E,2,0)) | I21: =IF(D21="(연결)","",VLOOKUP(D21,'46-288'!D:E,2,0)) | J21: =IF(D21="(연결)","",VLOOKUP(D21,'46-288-1'!D:E,2,0)) | K21: =IF(D21="(연결)","",VLOOKUP(D21,'115-144'!D:E,2,0))
A22: 2 | B22: 13 | D22: (연결) | E22: 13 | F22: =IF(D22="(연결)","",VLOOKUP(D22,'44-144'!D:E,2,0)) | G22: =IF(D22="(연결)","",VLOOKUP(D22,'44-288'!D:E,2,0)) | H22: =IF(D22="(연결)","",VLOOKUP(D22,'44-288-1'!D:E,2,0)) | I22: =IF(D22="(연결)","",VLOOKUP(D22,'46-288'!D:E,2,0)) | J22: =IF(D22="(연결)","",VLOOKUP(D22,'46-288-1'!D:E,2,0)) | K22: =IF(D22="(연결)","",VLOOKUP(D22,'115-144'!D:E,2,0)) | N22: ~ | O22: N
A23: 2 | B23: 14 | D23: (연결) | E23: 14 | F23: =IF(D23="(연결)","",VLOOKUP(D23,'44-144'!D:E,2,0)) | G23: =IF(D23="(연결)","",VLOOKUP(D23,'44-288'!D:E,2,0)) | H23: =IF(D23="(연결)","",VLOOKUP(D23,'44-288-1'!D:E,2,0)) | I23: =IF(D23="(연결)","",VLOOKUP(D23,'46-288'!D:E,2,0)) | J23: =IF(D23="(연결)","",VLOOKUP(D23,'46-288-1'!D:E,2,0)) | K23: =IF(D23="(연결)","",VLOOKUP(D23,'115-144'!D:E,2,0)) | N23: ~ | O23: N
A24: 2 | B24: 15 | C24: 운영중(OK) | D24: 9842957 | E24: 15 | F24: =IF(D24="(연결)","",VLOOKUP(D24,'44-144'!D:E,2,0)) -> #N/A | G24: =IF(D24="(연결)","",VLOOKUP(D24,'44-288'!D:E,2,0)) -> 211 | H24: =IF(D24="(연결)","",VLOOKUP(D24,'44-288-1'!D:E,2,0)) -> #N/A | I24: =IF(D24="(연결)","",VLOOKUP(D24,'46-288'!D:E,2,0)) -> #N/A | J24: =IF(D24="(연결)","",VLOOKUP(D24,'46-288-1'!D:E,2,0)) -> #N/A | K24: =IF(D24="(연결)","",VLOOKUP(D24,'115-144'!D:E,2,0)) -> #N/A | L24: MD11-7 | M24: 247 | N24: 인천간석사옥/인천종합국사(1층)~500087838775_인천지하철2호선_모래내시장역/[중]남동구청역 지하2층 본선 [HLB_인천간석C4_3330A_남동구청_승_인천2호선(1500062733.1600209034.1500062766)] | O24: N | P24: LC/PC-LC/PC | Q24: 30 | R24: 4G DU C | S24: HLB_인천간석C4_3330A | T24: 기타 | AC24: 인천간석사옥/인천종합국사(1층) | AH24: 500087838775_인천지하철2호선_모래내시장역/[중]남동구청역 지하2층 본선
A25: 2 | B25: 16 | C25: 운영중(OK) | D25: 9842970 | E25: 16 | F25: =IF(D25="(연결)","",VLOOKUP(D25,'44-144'!D:E,2,0)) -> #N/A | G25: =IF(D25="(연결)","",VLOOKUP(D25,'44-288'!D:E,2,0)) -> 212 | H25: =IF(D25="(연결)","",VLOOKUP(D25,'44-288-1'!D:E,2,0)) -> #N/A | I25: =IF(D25="(연결)","",VLOOKUP(D25,'46-288'!D:E,2,0)) -> #N/A | J25: =IF(D25="(연결)","",VLOOKUP(D25,'46-288-1'!D:E,2,0)) -> #N/A | K25: =IF(D25="(연결)","",VLOOKUP(D25,'115-144'!D:E,2,0)) -> #N/A | L25: MD11-8 | M25: 248 | N25: 인천간석사옥/인천종합국사(1층)~500087838775_인천지하철2호선_모래내시장역/[중]남동구청역 지하2층 본선 [HLB_인천간석C4_3320A_남동구청_대_인천2호선(1500062731.1600209031.1500062744)] | O25: N | P25: LC/PC-LC/PC | Q25: 30 | R25: 4G DU C | S25: HLB_인천간석C4_3320A | T25: 기타 | AC25: 인천간석사옥/인천종합국사(1층) | AH25: 500087838775_인천지하철2호선_모래내시장역/[중]남동구청역 지하2층 본선
A26: 2 | B26: 17 | D26: (연결) | E26: 17 | F26: =IF(D26="(연결)","",VLOOKUP(D26,'44-144'!D:E,2,0)) | G26: =IF(D26="(연결)","",VLOOKUP(D26,'44-288'!D:E,2,0)) | H26: =IF(D26="(연결)","",VLOOKUP(D26,'44-288-1'!D:E,2,0)) | I26: =IF(D26="(연결)","",VLOOKUP(D26,'46-288'!D:E,2,0)) | J26: =IF(D26="(연결)","",VLOOKUP(D26,'46-288-1'!D:E,2,0)) | K26: =IF(D26="(연결)","",VLOOKUP(D26,'115-144'!D:E,2,0)) | N26: ~ | O26: N
A27: 2 | B27: 18 | D27: (연결) | E27: 18 | F27: =IF(D27="(연결)","",VLOOKUP(D27,'44-144'!D:E,2,0)) | G27: =IF(D27="(연결)","",VLOOKUP(D27,'44-288'!D:E,2,0)) | H27: =IF(D27="(연결)","",VLOOKUP(D27,'44-288-1'!D:E,2,0)) | I27: =IF(D27="(연결)","",VLOOKUP(D27,'46-288'!D:E,2,0)) | J27: =IF(D27="(연결)","",VLOOKUP(D27,'46-288-1'!D:E,2,0)) | K27: =IF(D27="(연결)","",VLOOKUP(D27,'115-144'!D:E,2,0)) | N27: ~ | O27: N
A28: 2 | B28: 19 | C28: 운영중(OK) | D28: 3061840392 | E28: 19 | F28: =IF(D28="(연결)","",VLOOKUP(D28,'44-144'!D:E,2,0)) -> 71 | G28: =IF(D28="(연결)","",VLOOKUP(D28,'44-288'!D:E,2,0)) -> #N/A | H28: =IF(D28="(연결)","",VLOOKUP(D28,'44-288-1'!D:E,2,0)) -> #N/A | I28: =IF(D28="(연결)","",VLOOKUP(D28,'46-288'!D:E,2,0)) -> #N/A | J28: =IF(D28="(연결)","",VLOOKUP(D28,'46-288-1'!D:E,2,0)) -> #N/A | K28: =IF(D28="(연결)","",VLOOKUP(D28,'115-144'!D:E,2,0)) -> #N/A | L28: MD12-23 | M28: 287 | N28: 인천간석사옥/인천종합국사(1층)~500104297707/500252399656_인천발달장애인훈련센터 [[PTN][95INIHCA51 S.1-P2 ~ 95KEADBD_INC S.1-P1] [500252399656_인천발달장애인훈련센터]] | O28: N | P28: LC/PC-LC/PC | Q28: 30 | R28: A00-09 | S28: UTRANS-7320_GX8/Port-P2 | T28: 기타 | AC28: 인천간석사옥/인천종합국사(1층) | AD28: UTRANS-7320 | AE28: 95INIHCA51 | AF28: 95INIHCA51 | AG28: P2 | AH28: 500104297707/500252399656_인천발달장애인훈련센터 | AI28: UTRANS-7400C2 | AJ28: 95KEADBD_INC | AK28: 95KEADBD_INC | AL28: P1
A29: 2 | B29: 20 | C29: 운영중(OK) | D29: 3061840393 | E29: 20 | F29: =IF(D29="(연결)","",VLOOKUP(D29,'44-144'!D:E,2,0)) -> 72 | G29: =IF(D29="(연결)","",VLOOKUP(D29,'44-288'!D:E,2,0)) -> #N/A | H29: =IF(D29="(연결)","",VLOOKUP(D29,'44-288-1'!D:E,2,0)) -> #N/A | I29: =IF(D29="(연결)","",VLOOKUP(D29,'46-288'!D:E,2,0)) -> #N/A | J29: =IF(D29="(연결)","",VLOOKUP(D29,'46-288-1'!D:E,2,0)) -> #N/A | K29: =IF(D29="(연결)","",VLOOKUP(D29,'115-144'!D:E,2,0)) -> #N/A | L29: MD12-24 | M29: 288 | N29: 인천간석사옥/인천종합국사(1층)~500104297707/500252399656_인천발달장애인훈련센터 [[PTN][95INIHCA51 S.1-P2 ~ 95KEADBD_INC S.1-P1] [500252399656_인천발달장애인훈련센터]] | O29: N | P29: LC/PC-LC/PC | Q29: 30 | R29: A00-09 | S29: UTRANS-7320_GX8/Port-P2 | T29: 기타 | AC29: 인천간석사옥/인천종합국사(1층) | AD29: UTRANS-7320 | AE29: 95INIHCA51 | AF29: 95INIHCA51 | AG29: P2 | AH29: 500104297707/500252399656_인천발달장애인훈련센터 | AI29: UTRANS-7400C2 | AJ29: 95KEADBD_INC | AK29: 95KEADBD_INC | AL29: P1
A30: 2 | B30: 21 | D30: (연결) | E30: 21 | F30: =IF(D30="(연결)","",VLOOKUP(D30,'44-144'!D:E,2,0)) | G30: =IF(D30="(연결)","",VLOOKUP(D30,'44-288'!D:E,2,0)) | H30: =IF(D30="(연결)","",VLOOKUP(D30,'44-288-1'!D:E,2,0)) | I30: =IF(D30="(연결)","",VLOOKUP(D30,'46-288'!D:E,2,0)) | J30: =IF(D30="(연결)","",VLOOKUP(D30,'46-288-1'!D:E,2,0)) | K30: =IF(D30="(연결)","",VLOOKUP(D30,'115-144'!D:E,2,0)) | N30: ~ | O30: N
A31: 2 | B31: 22 | D31: (연결) | E31: 22 | F31: =IF(D31="(연결)","",VLOOKUP(D31,'44-144'!D:E,2,0)) | G31: =IF(D31="(연결)","",VLOOKUP(D31,'44-288'!D:E,2,0)) | H31: =IF(D31="(연결)","",VLOOKUP(D31,'44-288-1'!D:E,2,0)) | I31: =IF(D31="(연결)","",VLOOKUP(D31,'46-288'!D:E,2,0)) | J31: =IF(D31="(연결)","",VLOOKUP(D31,'46-288-1'!D:E,2,0)) | K31: =IF(D31="(연결)","",VLOOKUP(D31,'115-144'!D:E,2,0)) | N31: ~ | O31: N
A32: 2 | B32: 23 | D32: (연결) | E32: 23 | F32: =IF(D32="(연결)","",VLOOKUP(D32,'44-144'!D:E,2,0)) | G32: =IF(D32="(연결)","",VLOOKUP(D32,'44-288'!D:E,2,0)) | H32: =IF(D32="(연결)","",VLOOKUP(D32,'44-288-1'!D:E,2,0)) | I32: =IF(D32="(연결)","",VLOOKUP(D32,'46-288'!D:E,2,0)) | J32: =IF(D32="(연결)","",VLOOKUP(D32,'46-288-1'!D:E,2,0)) | K32: =IF(D32="(연결)","",VLOOKUP(D32,'115-144'!D:E,2,0)) | N32: ~ | O32: N
A33: 2 | B33: 24 | D33: (연결) | E33: 24 | F33: =IF(D33="(연결)","",VLOOKUP(D33,'44-144'!D:E,2,0)) | G33: =IF(D33="(연결)","",VLOOKUP(D33,'44-288'!D:E,2,0)) | H33: =IF(D33="(연결)","",VLOOKUP(D33,'44-288-1'!D:E,2,0)) | I33: =IF(D33="(연결)","",VLOOKUP(D33,'46-288'!D:E,2,0)) | J33: =IF(D33="(연결)","",VLOOKUP(D33,'46-288-1'!D:E,2,0)) | K33: =IF(D33="(연결)","",VLOOKUP(D33,'115-144'!D:E,2,0)) | N33: ~ | O33: N
A34: Unit#3 | F34: =IF(D34="(연결)","",VLOOKUP(D34,'44-144'!D:E,2,0)) | G34: =IF(D34="(연결)","",VLOOKUP(D34,'44-288'!D:E,2,0)) | H34: =IF(D34="(연결)","",VLOOKUP(D34,'44-288-1'!D:E,2,0)) | I34: =IF(D34="(연결)","",VLOOKUP(D34,'46-288'!D:E,2,0)) | J34: =IF(D34="(연결)","",VLOOKUP(D34,'46-288-1'!D:E,2,0)) | K34: =IF(D34="(연결)","",VLOOKUP(D34,'115-144'!D:E,2,0))
A35: 3 | B35: 25 | D35: (연결) | E35: 25 | F35: =IF(D35="(연결)","",VLOOKUP(D35,'44-144'!D:E,2,0)) | G35: =IF(D35="(연결)","",VLOOKUP(D35,'44-288'!D:E,2,0)) | H35: =IF(D35="(연결)","",VLOOKUP(D35,'44-288-1'!D:E,2,0)) | I35: =IF(D35="(연결)","",VLOOKUP(D35,'46-288'!D:E,2,0)) | J35: =IF(D35="(연결)","",VLOOKUP(D35,'46-288-1'!D:E,2,0)) | K35: =IF(D35="(연결)","",VLOOKUP(D35,'115-144'!D:E,2,0)) | N35: 8820C421[8820C415 사각H]~인천간석사옥/인천종합국사(1층) | O35: N
A36: 3 | B36: 26 | D36: (연결) | E36: 26 | F36: =IF(D36="(연결)","",VLOOKUP(D36,'44-144'!D:E,2,0)) | G36: =IF(D36="(연결)","",VLOOKUP(D36,'44-288'!D:E,2,0)) | H36: =IF(D36="(연결)","",VLOOKUP(D36,'44-288-1'!D:E,2,0)) | I36: =IF(D36="(연결)","",VLOOKUP(D36,'46-288'!D:E,2,0)) | J36: =IF(D36="(연결)","",VLOOKUP(D36,'46-288-1'!D:E,2,0)) | K36: =IF(D36="(연결)","",VLOOKUP(D36,'115-144'!D:E,2,0)) | N36: 인천간석사옥/인천종합국사(1층)~8820P291[8720P291] | O36: N
A37: 3 | B37: 27 | D37: (연결) | E37: 27 | F37: =IF(D37="(연결)","",VLOOKUP(D37,'44-144'!D:E,2,0)) | G37: =IF(D37="(연결)","",VLOOKUP(D37,'44-288'!D:E,2,0)) | H37: =IF(D37="(연결)","",VLOOKUP(D37,'44-288-1'!D:E,2,0)) | I37: =IF(D37="(연결)","",VLOOKUP(D37,'46-288'!D:E,2,0)) | J37: =IF(D37="(연결)","",VLOOKUP(D37,'46-288-1'!D:E,2,0)) | K37: =IF(D37="(연결)","",VLOOKUP(D37,'115-144'!D:E,2,0)) | N37: 인천간석사옥/인천종합국사(1층)~8820P291[8720P291] | O37: N
A38: 3 | B38: 28 | D38: (연결) | E38: 28 | F38: =IF(D38="(연결)","",VLOOKUP(D38,'44-144'!D:E,2,0)) | G38: =IF(D38="(연결)","",VLOOKUP(D38,'44-288'!D:E,2,0)) | H38: =IF(D38="(연결)","",VLOOKUP(D38,'44-288-1'!D:E,2,0)) | I38: =IF(D38="(연결)","",VLOOKUP(D38,'46-288'!D:E,2,0)) | J38: =IF(D38="(연결)","",VLOOKUP(D38,'46-288-1'!D:E,2,0)) | K38: =IF(D38="(연결)","",VLOOKUP(D38,'115-144'!D:E,2,0)) | N38: 인천간석사옥/인천종합국사(1층)~8820P291[8720P291] | O38: N
A39: 3 | B39: 29 | D39: (연결) | E39: 29 | F39: =IF(D39="(연결)","",VLOOKUP(D39,'44-144'!D:E,2,0)) | G39: =IF(D39="(연결)","",VLOOKUP(D39,'44-288'!D:E,2,0)) | H39: =IF(D39="(연결)","",VLOOKUP(D39,'44-288-1'!D:E,2,0)) | I39: =IF(D39="(연결)","",VLOOKUP(D39,'46-288'!D:E,2,0)) | J39: =IF(D39="(연결)","",VLOOKUP(D39,'46-288-1'!D:E,2,0)) | K39: =IF(D39="(연결)","",VLOOKUP(D39,'115-144'!D:E,2,0)) | N39: 8820C421[8820C415 사각H]~인천간석사옥/인천종합국사(1층) | O39: N
A40: 3 | B40: 30 | D40: (연결) | E40: 30 | F40: =IF(D40="(연결)","",VLOOKUP(D40,'44-144'!D:E,2,0)) | G40: =IF(D40="(연결)","",VLOOKUP(D40,'44-288'!D:E,2,0)) | H40: =IF(D40="(연결)","",VLOOKUP(D40,'44-288-1'!D:E,2,0)) | I40: =IF(D40="(연결)","",VLOOKUP(D40,'46-288'!D:E,2,0)) | J40: =IF(D40="(연결)","",VLOOKUP(D40,'46-288-1'!D:E,2,0)) | K40: =IF(D40="(연결)","",VLOOKUP(D40,'115-144'!D:E,2,0)) | N40: 8820C421[8820C415 사각H]~인천간석사옥/인천종합국사(1층) | O40: N
A41: 3 | B41: 31 | D41: (연결) | E41: 31 | F41: =IF(D41="(연결)","",VLOOKUP(D41,'44-144'!D:E,2,0)) | G41: =IF(D41="(연결)","",VLOOKUP(D41,'44-288'!D:E,2,0)) | H41: =IF(D41="(연결)","",VLOOKUP(D41,'44-288-1'!D:E,2,0)) | I41: =IF(D41="(연결)","",VLOOKUP(D41,'46-288'!D:E,2,0)) | J41: =IF(D41="(연결)","",VLOOKUP(D41,'46-288-1'!D:E,2,0)) | K41: =IF(D41="(연결)","",VLOOKUP(D41,'115-144'!D:E,2,0)) | N41: 인천간석사옥/인천종합국사(1층)~8820P291[8720P291] | O41: N
...

Sheet (1-288)
A3: 선로ID | B3: 605791445 | D3: 선로명 | AE3: (철거예정)(기간망추가수용금지)B00-03 MD1~24(FC) | AF3: 규격 | AG3: 288C | AH3: N/W구분 | AI3: 혼합선로
A4: 시점 | B4: 8720H253 | AF4: LOT No. | AG4: 6178 | AH4: 자산번호
A5: 종점 | B5: 인천간석사옥/인천종합국사(1층) | AF5: 자재코드 | AG5: 530058 | AH5: 자재명 | AI5: 광케이블,288C,가공
B6: 신설 | K6: 표기완 | AB6: ???
A7: UNIT | B7: 선번 | C7: 구성상태 | D7: 코어ID | E7: 선번 | F7: 115-144 | G7: (115-288) | H7: 44-144 | I7: 44-144-1 | J7: 44-288 | K7: 44-288-1 | L7: (44-288) | M7: 46-288 | N7: 46-288-1 | O7: 46-288-2 | P7: (46-288) | Q7: 72-72 | R7: 72-144 | S7: 73-12 | T7: 104-12 | U7: 105-36 | V7: 105-72 | W7: 130-72 | X7: 150-36-2 | Y7: 166-144 | Z7: 187-144-2 | AA7: 201-36 | AB7: 201-72 | AC7: 201-72-2 | AD7: 134-36 | AE7: 코어명 | AF7: 광선로감시여부 | AG7: 중요여부 | AH7: 코어수용서비스 | AI7: 코어수용서비스상세 | AJ7: 수용서비스범위 | AK7: 영향고객수 | AL7: 연계회선번호 | AM7: 가입자번호 | AN7: 단선(불량)여부 | AO7: 직결공사번호 | AP7: Network명 | AQ7: Network ID | AR7: 상위국설치장소명 | AS7: 상위국장비모델 | AT7: 상위국장비명 | AU7: 상위국TID | AV7: 상위국AID(port) | AW7: 하위국설치장소명 | AX7: 하위국장비모델 | AY7: 하위국장비명 | AZ7: 하위국TID | BA7: 하위국AID(port)
A8: Unit#1 | F8: =IF(D8="(연결)","",VLOOKUP(D8,'115-144'!D:E,2,0)) | G8: =IF(D8="(연결)","",VLOOKUP(D8,'(115-288)'!D:E,2,0)) | H8: =IF(D8="(연결)","",VLOOKUP(D8,'44-144'!D:E,2,0)) | I8: =IF(D8="(연결)","",VLOOKUP(D8,'44-144-1'!D:E,2,0)) | J8: =IF(D8="(연결)","",VLOOKUP(D8,'44-288'!D:E,2,0)) | K8: =IF(D8="(연결)","",VLOOKUP(D8,'44-288-1'!D:E,2,0)) | L8: =IF(D8="(연결)","",VLOOKUP(D8,'(44-288)'!D:E,2,0)) | M8: =IF(D8="(연결)","",VLOOKUP(D8,'46-288'!D:E,2,0)) | N8: =IF(D8="(연결)","",VLOOKUP(D8,'46-288-1'!D:E,2,0)) | O8: =IF(D8="(연결)","",VLOOKUP(D8,'46-288-2'!D:E,2,0)) | P8: =IF(D8="(연결)","",VLOOKUP(D8,'(46-288)'!D:E,2,0)) | Q8: =IF(D8="(연결)","",VLOOKUP(D8,'72-72'!D:E,2,0)) | R8: =IF(D8="(연결)","",VLOOKUP(D8,'72-144'!D:E,2,0)) | S8: =IF(D8="(연결)","",VLOOKUP(D8,'73-12'!D:E,2,0)) | T8: =IF(D8="(연결)","",VLOOKUP(D8,'104-12'!D:E,2,0)) | U8: =IF(D8="(연결)","",VLOOKUP(D8,'105-36'!D:E,2,0)) | X8: =IF(D8="(연결)","",VLOOKUP(D8,'150-36-2'!D:E,2,0)) | Y8: =IF(D8="(연결)","",VLOOKUP(D8,'166-144'!D:E,2,0)) | Z8: =IF(D8="(연결)","",VLOOKUP(D8,'187-144-2'!D:E,2,0)) | AA8: =IF(D8="(연결)","",VLOOKUP(D8,'201-36'!D:E,2,0)) | AB8: =IF(D8="(연결)","",VLOOKUP(D8,'201-72'!D:E,2,0)) | AD8: =IF(D8="(연결)","",VLOOKUP(D8,'134-36'!D:E,2,0))
A9: 1 | B9: 1 | C9: 운영중(OK) | D9: 7053387 | E9: 1 | F9: =IF(D9="(연결)","",VLOOKUP(D9,'115-144'!D:E,2,0)) -> 1 | G9: =IF(D9="(연결)","",VLOOKUP(D9,'(115-288)'!D:E,2,0)) -> 1 | H9: =IF(D9="(연결)","",VLOOKUP(D9,'44-144'!D:E,2,0)) -> #N/A | I9: =IF(D9="(연결)","",VLOOKUP(D9,'44-144-1'!D:E,2,0)) -> #N/A | J9: =IF(D9="(연결)","",VLOOKUP(D9,'44-288'!D:E,2,0)) -> #N/A | K9: =IF(D9="(연결)","",VLOOKUP(D9,'44-288-1'!D:E,2,0)) -> #N/A | L9: =IF(D9="(연결)","",VLOOKUP(D9,'(44-288)'!D:E,2,0)) -> #N/A | M9: =IF(D9="(연결)","",VLOOKUP(D9,'46-288'!D:E,2,0)) -> #N/A | N9: =IF(D9="(연결)","",VLOOKUP(D9,'46-288-1'!D:E,2,0)) -> #N/A | O9: =IF(D9="(연결)","",VLOOKUP(D9,'46-288-2'!D:E,2,0)) -> #N/A | P9: =IF(D9="(연결)","",VLOOKUP(D9,'(46-288)'!D:E,2,0)) -> #N/A | Q9: =IF(D9="(연결)","",VLOOKUP(D9,'72-72'!D:E,2,0)) -> #N/A | R9: =IF(D9="(연결)","",VLOOKUP(D9,'72-144'!D:E,2,0)) -> #N/A | S9: =IF(D9="(연결)","",VLOOKUP(D9,'73-12'!D:E,2,0)) -> #N/A | T9: =IF(D9="(연결)","",VLOOKUP(D9,'104-12'!D:E,2,0)) -> #N/A | U9: =IF(D9="(연결)","",VLOOKUP(D9,'105-36'!D:E,2,0)) -> #N/A | V9: =IF(D9="(연결)","",VLOOKUP(D9,'105-72'!D:E,2,0)) -> #N/A | W9: =IF(D9="(연결)","",VLOOKUP(D9,'130-72'!D:E,2,0)) -> #N/A | X9: =IF(D9="(연결)","",VLOOKUP(D9,'150-36-2'!D:E,2,0)) -> #N/A | Y9: =IF(D9="(연결)","",VLOOKUP(D9,'166-144'!D:E,2,0)) -> #N/A | Z9: =IF(D9="(연결)","",VLOOKUP(D9,'187-144-2'!D:E,2,0)) -> #N/A | AA9: =IF(D9="(연결)","",VLOOKUP(D9,'201-36'!D:E,2,0)) -> #N/A | AB9: =IF(D9="(연결)","",VLOOKUP(D9,'201-72'!D:E,2,0)) -> #N/A | AC9: =IF(D9="(연결)","",VLOOKUP(D9,'201-72-2'!D:E,2,0)) -> #N/A | AD9: =IF(D9="(연결)","",VLOOKUP(D9,'134-36'!D:E,2,0)) -> #N/A | AE9: 인천간석사옥/인천종합국사(1층)~인천종합국사_102093/102103_1_0_0_8821R052_2:8RN [인천종합국사_102103_1_0_0_8821R052_2:8RN] | AF9: N | AH9: 홈/기업 | AI9: FTTH 1차 RN | AR9: 인천간석사옥/인천종합국사(1층) | AS9: V8500 | AT9: H_TONGHAB-V8500-2-TPS | AU9: TONGHAB-V8500-2-TPS | AV9: 3 | AW9: 인천종합국사_102093/102103_1_0_0_8821R052_2:8RN | AX9: RN 2:8 | AY9: 구월25셀_2:8RN_8821R052(가공형간석동1_210)_종합V5724#7_920 | AZ9: 인천간석_207092/207102_1_0_0_8821R052(가공형간석동1_210)RN 2:8 | BA9: I_P1
A10: 1 | B10: 2 | C10: 운영중(OK) | D10: 7053386 | E10: 2 | F10: =IF(D10="(연결)","",VLOOKUP(D10,'115-144'!D:E,2,0)) -> 2 | G10: =IF(D10="(연결)","",VLOOKUP(D10,'(115-288)'!D:E,2,0)) -> 2 | H10: =IF(D10="(연결)","",VLOOKUP(D10,'44-144'!D:E,2,0)) -> #N/A | I10: =IF(D10="(연결)","",VLOOKUP(D10,'44-144-1'!D:E,2,0)) -> #N/A | J10: =IF(D10="(연결)","",VLOOKUP(D10,'44-288'!D:E,2,0)) -> #N/A | K10: =IF(D10="(연결)","",VLOOKUP(D10,'44-288-1'!D:E,2,0)) -> #N/A | L10: =IF(D10="(연결)","",VLOOKUP(D10,'(44-288)'!D:E,2,0)) -> #N/A | M10: =IF(D10="(연결)","",VLOOKUP(D10,'46-288'!D:E,2,0)) -> #N/A | N10: =IF(D10="(연결)","",VLOOKUP(D10,'46-288-1'!D:E,2,0)) -> #N/A | O10: =IF(D10="(연결)","",VLOOKUP(D10,'46-288-2'!D:E,2,0)) -> #N/A | P10: =IF(D10="(연결)","",VLOOKUP(D10,'(46-288)'!D:E,2,0)) -> #N/A | Q10: =IF(D10="(연결)","",VLOOKUP(D10,'72-72'!D:E,2,0)) -> #N/A | R10: =IF(D10="(연결)","",VLOOKUP(D10,'72-144'!D:E,2,0)) -> #N/A | S10: =IF(D10="(연결)","",VLOOKUP(D10,'73-12'!D:E,2,0)) -> #N/A | T10: =IF(D10="(연결)","",VLOOKUP(D10,'104-12'!D:E,2,0)) -> #N/A | U10: =IF(D10="(연결)","",VLOOKUP(D10,'105-36'!D:E,2,0)) -> #N/A | V10: =IF(D10="(연결)","",VLOOKUP(D10,'105-72'!D:E,2,0)) -> #N/A | W10: =IF(D10="(연결)","",VLOOKUP(D10,'130-72'!D:E,2,0)) -> #N/A | X10: =IF(D10="(연결)","",VLOOKUP(D10,'150-36-2'!D:E,2,0)) -> #N/A | Y10: =IF(D10="(연결)","",VLOOKUP(D10,'166-144'!D:E,2,0)) -> #N/A | Z10: =IF(D10="(연결)","",VLOOKUP(D10,'187-144-2'!D:E,2,0)) -> #N/A | AA10: =IF(D10="(연결)","",VLOOKUP(D10,'201-36'!D:E,2,0)) -> #N/A | AB10: =IF(D10="(연결)","",VLOOKUP(D10,'201-72'!D:E,2,0)) -> #N/A | AC10: =IF(D10="(연결)","",VLOOKUP(D10,'201-72-2'!D:E,2,0)) -> #N/A | AD10: =IF(D10="(연결)","",VLOOKUP(D10,'134-36'!D:E,2,0)) -> #N/A | AE10: 인천간석사옥/인천종합국사(1층)~인천종합국사_111094/111104_1_0_0[8721X312] 2:8RN [인천종합국사_111104_1_0_0[8721X312] 2:8RN] | AF10: N | AH10: 홈/기업 | AI10: FTTH 1차 RN | AR10: 인천간석사옥/인천종합국사(1층) | AS10: V8500 | AT10: H_JongHab-V8500-11-SME | AU10: H_JongHab-V8500-11-SME | AV10: 4 | AW10: 인천종합국사_111094/111104_1_0_0[8721X312] 2:8RN | AX10: RN 2:8 | AY10: 인천종합 GS/B8-02-1[8721X312] | AZ10: 인천간석_208011/208021_1_0_0[8721X312] 2:8RN | BA10: I_P2
A11: 1 | B11: 3 | C11: (해지)운영중(OK) | D11: 7053389 | E11: 3 | F11: =IF(D11="(연결)","",VLOOKUP(D11,'115-144'!D:E,2,0)) -> 3 | G11: =IF(D11="(연결)","",VLOOKUP(D11,'(115-288)'!D:E,2,0)) -> 3 | H11: =IF(D11="(연결)","",VLOOKUP(D11,'44-144'!D:E,2,0)) -> #N/A | I11: =IF(D11="(연결)","",VLOOKUP(D11,'44-144-1'!D:E,2,0)) -> #N/A | J11: =IF(D11="(연결)","",VLOOKUP(D11,'44-288'!D:E,2,0)) -> #N/A | K11: =IF(D11="(연결)","",VLOOKUP(D11,'44-288-1'!D:E,2,0)) -> #N/A | L11: =IF(D11="(연결)","",VLOOKUP(D11,'(44-288)'!D:E,2,0)) -> #N/A | M11: =IF(D11="(연결)","",VLOOKUP(D11,'46-288'!D:E,2,0)) -> #N/A | N11: =IF(D11="(연결)","",VLOOKUP(D11,'46-288-1'!D:E,2,0)) -> #N/A | O11: =IF(D11="(연결)","",VLOOKUP(D11,'46-288-2'!D:E,2,0)) -> #N/A | P11: =IF(D11="(연결)","",VLOOKUP(D11,'(46-288)'!D:E,2,0)) -> #N/A | Q11: =IF(D11="(연결)","",VLOOKUP(D11,'72-72'!D:E,2,0)) -> #N/A | R11: =IF(D11="(연결)","",VLOOKUP(D11,'72-144'!D:E,2,0)) -> #N/A | S11: =IF(D11="(연결)","",VLOOKUP(D11,'73-12'!D:E,2,0)) -> #N/A | T11: =IF(D11="(연결)","",VLOOKUP(D11,'104-12'!D:E,2,0)) -> #N/A | U11: =IF(D11="(연결)","",VLOOKUP(D11,'105-36'!D:E,2,0)) -> #N/A | V11: =IF(D11="(연결)","",VLOOKUP(D11,'105-72'!D:E,2,0)) -> #N/A | W11: =IF(D11="(연결)","",VLOOKUP(D11,'130-72'!D:E,2,0)) -> #N/A | X11: =IF(D11="(연결)","",VLOOKUP(D11,'150-36-2'!D:E,2,0)) -> #N/A | Y11: =IF(D11="(연결)","",VLOOKUP(D11,'166-144'!D:E,2,0)) -> #N/A | Z11: =IF(D11="(연결)","",VLOOKUP(D11,'187-144-2'!D:E,2,0)) -> #N/A | AA11: =IF(D11="(연결)","",VLOOKUP(D11,'201-36'!D:E,2,0)) -> #N/A | AB11: =IF(D11="(연결)","",VLOOKUP(D11,'201-72'!D:E,2,0)) -> #N/A | AC11: =IF(D11="(연결)","",VLOOKUP(D11,'201-72-2'!D:E,2,0)) -> #N/A | AD11: =IF(D11="(연결)","",VLOOKUP(D11,'134-36'!D:E,2,0)) -> #N/A | AE11: 인천간석사옥/인천종합국사(1층)~인천종합 GS/B?-??-1[8820A081] [인천종합 만수 MS/B?-??-1[8820A081]] | AF11: N | AH11: 홈/기업 | AI11: FTTH 1차 RN | AR11: 인천간석사옥/인천종합국사(1층) | AW11: 인천종합 GS/B?-??-1[8820A081]
A12: 1 | B12: 4 | C12: 운영중(OK) | D12: 9842945 | E12: 4 | F12: =IF(D12="(연결)","",VLOOKUP(D12,'115-144'!D:E,2,0)) -> #N/A | G12: =IF(D12="(연결)","",VLOOKUP(D12,'(115-288)'!D:E,2,0)) -> #N/A | H12: =IF(D12="(연결)","",VLOOKUP(D12,'44-144'!D:E,2,0)) -> #N/A | I12: =IF(D12="(연결)","",VLOOKUP(D12,'44-144-1'!D:E,2,0)) -> #N/A | J12: =IF(D12="(연결)","",VLOOKUP(D12,'44-288'!D:E,2,0)) -> 205 | K12: =IF(D12="(연결)","",VLOOKUP(D12,'44-288-1'!D:E,2,0)) -> #N/A | L12: =IF(D12="(연결)","",VLOOKUP(D12,'(44-288)'!D:E,2,0)) -> 41 | M12: =IF(D12="(연결)","",VLOOKUP(D12,'46-288'!D:E,2,0)) -> #N/A | N12: =IF(D12="(연결)","",VLOOKUP(D12,'46-288-1'!D:E,2,0)) -> #N/A | O12: =IF(D12="(연결)","",VLOOKUP(D12,'46-288-2'!D:E,2,0)) -> #N/A | P12: =IF(D12="(연결)","",VLOOKUP(D12,'(46-288)'!D:E,2,0)) -> #N/A | Q12: =IF(D12="(연결)","",VLOOKUP(D12,'72-72'!D:E,2,0)) -> #N/A | R12: =IF(D12="(연결)","",VLOOKUP(D12,'72-144'!D:E,2,0)) -> #N/A | S12: =IF(D12="(연결)","",VLOOKUP(D12,'73-12'!D:E,2,0)) -> #N/A | T12: =IF(D12="(연결)","",VLOOKUP(D12,'104-12'!D:E,2,0)) -> #N/A | U12: =IF(D12="(연결)","",VLOOKUP(D12,'105-36'!D:E,2,0)) -> #N/A | V12: =IF(D12="(연결)","",VLOOKUP(D12,'105-72'!D:E,2,0)) -> #N/A | W12: =IF(D12="(연결)","",VLOOKUP(D12,'130-72'!D:E,2,0)) -> #N/A | X12: =IF(D12="(연결)","",VLOOKUP(D12,'150-36-2'!D:E,2,0)) -> #N/A | Y12: =IF(D12="(연결)","",VLOOKUP(D12,'166-144'!D:E,2,0)) -> #N/A | Z12: =IF(D12="(연결)","",VLOOKUP(D12,'187-144-2'!D:E,2,0)) -> #N/A | AA12: =IF(D12="(연결)","",VLOOKUP(D12,'201-36'!D:E,2,0)) -> #N/A | AB12: =IF(D12="(연결)","",VLOOKUP(D12,'201-72'!D:E,2,0)) -> #N/A | AC12: =IF(D12="(연결)","",VLOOKUP(D12,'201-72-2'!D:E,2,0)) -> #N/A | AD12: =IF(D12="(연결)","",VLOOKUP(D12,'134-36'!D:E,2,0)) -> #N/A | AE12: 인천간석사옥/인천종합국사(1층)~500087838775_인천지하철2호선_모래내시장역/[중]남동구청역 지하2층 본선 [HLB_인천간석C3_3330A_만수_터_인천2호선(1500062728.1600209028.1500062761)] | AF12: N | AH12: 기타 | AI12: 기타 | AR12: 인천간석사옥/인천종합국사(1층) | AW12: 500087838775_인천지하철2호선_모래내시장역/[중]남동구청역 지하2층 본선
A13: 1 | B13: 5 | C13: 운영중(OK) | D13: 9842947 | E13: 5 | F13: =IF(D13="(연결)","",VLOOKUP(D13,'115-144'!D:E,2,0)) -> #N/A | G13: =IF(D13="(연결)","",VLOOKUP(D13,'(115-288)'!D:E,2,0)) -> #N/A | H13: =IF(D13="(연결)","",VLOOKUP(D13,'44-144'!D:E,2,0)) -> #N/A | I13: =IF(D13="(연결)","",VLOOKUP(D13,'44-144-1'!D:E,2,0)) -> #N/A | J13: =IF(D13="(연결)","",VLOOKUP(D13,'44-288'!D:E,2,0)) -> 206 | K13: =IF(D13="(연결)","",VLOOKUP(D13,'44-288-1'!D:E,2,0)) -> #N/A | L13: =IF(D13="(연결)","",VLOOKUP(D13,'(44-288)'!D:E,2,0)) -> 42 | M13: =IF(D13="(연결)","",VLOOKUP(D13,'46-288'!D:E,2,0)) -> #N/A | N13: =IF(D13="(연결)","",VLOOKUP(D13,'46-288-1'!D:E,2,0)) -> #N/A | O13: =IF(D13="(연결)","",VLOOKUP(D13,'46-288-2'!D:E,2,0)) -> #N/A | P13: =IF(D13="(연결)","",VLOOKUP(D13,'(46-288)'!D:E,2,0)) -> #N/A | Q13: =IF(D13="(연결)","",VLOOKUP(D13,'72-72'!D:E,2,0)) -> #N/A | R13: =IF(D13="(연결)","",VLOOKUP(D13,'72-144'!D:E,2,0)) -> #N/A | S13: =IF(D13="(연결)","",VLOOKUP(D13,'73-12'!D:E,2,0)) -> #N/A | T13: =IF(D13="(연결)","",VLOOKUP(D13,'104-12'!D:E,2,0)) -> #N/A | U13: =IF(D13="(연결)","",VLOOKUP(D13,'105-36'!D:E,2,0)) -> #N/A | V13: =IF(D13="(연결)","",VLOOKUP(D13,'105-72'!D:E,2,0)) -> #N/A | W13: =IF(D13="(연결)","",VLOOKUP(D13,'130-72'!D:E,2,0)) -> #N/A | X13: =IF(D13="(연결)","",VLOOKUP(D13,'150-36-2'!D:E,2,0)) -> #N/A | Y13: =IF(D13="(연결)","",VLOOKUP(D13,'166-144'!D:E,2,0)) -> #N/A | Z13: =IF(D13="(연결)","",VLOOKUP(D13,'187-144-2'!D:E,2,0)) -> #N/A | AA13: =IF(D13="(연결)","",VLOOKUP(D13,'201-36'!D:E,2,0)) -> #N/A | AB13: =IF(D13="(연결)","",VLOOKUP(D13,'201-72'!D:E,2,0)) -> #N/A | AC13: =IF(D13="(연결)","",VLOOKUP(D13,'201-72-2'!D:E,2,0)) -> #N/A | AD13: =IF(D13="(연결)","",VLOOKUP(D13,'134-36'!D:E,2,0)) -> #N/A | AE13: 인천간석사옥/인천종합국사(1층)~500087838775_인천지하철2호선_모래내시장역/[중]남동구청역 지하2층 본선 [HLB_인천간석C3_3320A_만수_터_인천2호선(1500062727.1600209027.1500062760)] | AF13: N | AH13: 기타 | AI13: 기타 | AR13: 인천간석사옥/인천종합국사(1층) | AW13: 500087838775_인천지하철2호선_모래내시장역/[중]남동구청역 지하2층 본선
A14: 1 | B14: 6 | C14: 운영중(OK) | D14: 9842951 | E14: 6 | F14: =IF(D14="(연결)","",VLOOKUP(D14,'115-144'!D:E,2,0)) -> #N/A | G14: =IF(D14="(연결)","",VLOOKUP(D14,'(115-288)'!D:E,2,0)) -> #N/A | H14: =IF(D14="(연결)","",VLOOKUP(D14,'44-144'!D:E,2,0)) -> #N/A | I14: =IF(D14="(연결)","",VLOOKUP(D14,'44-144-1'!D:E,2,0)) -> #N/A | J14: =IF(D14="(연결)","",VLOOKUP(D14,'44-288'!D:E,2,0)) -> 207 | K14: =IF(D14="(연결)","",VLOOKUP(D14,'44-288-1'!D:E,2,0)) -> #N/A | L14: =IF(D14="(연결)","",VLOOKUP(D14,'(44-288)'!D:E,2,0)) -> 43 | M14: =IF(D14="(연결)","",VLOOKUP(D14,'46-288'!D:E,2,0)) -> #N/A | N14: =IF(D14="(연결)","",VLOOKUP(D14,'46-288-1'!D:E,2,0)) -> #N/A | O14: =IF(D14="(연결)","",VLOOKUP(D14,'46-288-2'!D:E,2,0)) -> #N/A | P14: =IF(D14="(연결)","",VLOOKUP(D14,'(46-288)'!D:E,2,0)) -> #N/A | Q14: =IF(D14="(연결)","",VLOOKUP(D14,'72-72'!D:E,2,0)) -> #N/A | R14: =IF(D14="(연결)","",VLOOKUP(D14,'72-144'!D:E,2,0)) -> #N/A | S14: =IF(D14="(연결)","",VLOOKUP(D14,'73-12'!D:E,2,0)) -> #N/A | T14: =IF(D14="(연결)","",VLOOKUP(D14,'104-12'!D:E,2,0)) -> #N/A | U14: =IF(D14="(연결)","",VLOOKUP(D14,'105-36'!D:E,2,0)) -> #N/A | V14: =IF(D14="(연결)","",VLOOKUP(D14,'105-72'!D:E,2,0)) -> #N/A | W14: =IF(D14="(연결)","",VLOOKUP(D14,'130-72'!D:E,2,0)) -> #N/A | X14: =IF(D14="(연결)","",VLOOKUP(D14,'150-36-2'!D:E,2,0)) -> #N/A | Y14: =IF(D14="(연결)","",VLOOKUP(D14,'166-144'!D:E,2,0)) -> #N/A | Z14: =IF(D14="(연결)","",VLOOKUP(D14,'187-144-2'!D:E,2,0)) -> #N/A | AA14: =IF(D14="(연결)","",VLOOKUP(D14,'201-36'!D:E,2,0)) -> #N/A | AB14: =IF(D14="(연결)","",VLOOKUP(D14,'201-72'!D:E,2,0)) -> #N/A | AC14: =IF(D14="(연결)","",VLOOKUP(D14,'201-72-2'!D:E,2,0)) -> #N/A | AD14: =IF(D14="(연결)","",VLOOKUP(D14,'134-36'!D:E,2,0)) -> #N/A | AE14: 인천간석사옥/인천종합국사(1층)~500087838775_인천지하철2호선_모래내시장역/[중]남동구청역 지하2층 본선 [HLB_인천간석C3_3450A_만수_터_인천2호선(1500062730.1600209030.1500062763)] | AF14: N | AH14: 기타 | AI14: 기타 | AR14: 인천간석사옥/인천종합국사(1층) | AW14: 500087838775_인천지하철2호선_모래내시장역/[중]남동구청역 지하2층 본선
A15: 1 | B15: 7 | C15: 운영중(OK) | D15: 9842954 | E15: 7 | F15: =IF(D15="(연결)","",VLOOKUP(D15,'115-144'!D:E,2,0)) -> #N/A | G15: =IF(D15="(연결)","",VLOOKUP(D15,'(115-288)'!D:E,2,0)) -> #N/A | H15: =IF(D15="(연결)","",VLOOKUP(D15,'44-144'!D:E,2,0)) -> #N/A | I15: =IF(D15="(연결)","",VLOOKUP(D15,'44-144-1'!D:E,2,0)) -> #N/A | J15: =IF(D15="(연결)","",VLOOKUP(D15,'44-288'!D:E,2,0)) -> 208 | K15: =IF(D15="(연결)","",VLOOKUP(D15,'44-288-1'!D:E,2,0)) -> #N/A | L15: =IF(D15="(연결)","",VLOOKUP(D15,'(44-288)'!D:E,2,0)) -> 44 | M15: =IF(D15="(연결)","",VLOOKUP(D15,'46-288'!D:E,2,0)) -> #N/A | N15: =IF(D15="(연결)","",VLOOKUP(D15,'46-288-1'!D:E,2,0)) -> #N/A | O15: =IF(D15="(연결)","",VLOOKUP(D15,'46-288-2'!D:E,2,0)) -> #N/A | P15: =IF(D15="(연결)","",VLOOKUP(D15,'(46-288)'!D:E,2,0)) -> #N/A | Q15: =IF(D15="(연결)","",VLOOKUP(D15,'72-72'!D:E,2,0)) -> #N/A | R15: =IF(D15="(연결)","",VLOOKUP(D15,'72-144'!D:E,2,0)) -> #N/A | S15: =IF(D15="(연결)","",VLOOKUP(D15,'73-12'!D:E,2,0)) -> #N/A | T15: =IF(D15="(연결)","",VLOOKUP(D15,'104-12'!D:E,2,0)) -> #N/A | U15: =IF(D15="(연결)","",VLOOKUP(D15,'105-36'!D:E,2,0)) -> #N/A | V15: =IF(D15="(연결)","",VLOOKUP(D15,'105-72'!D:E,2,0)) -> #N/A | W15: =IF(D15="(연결)","",VLOOKUP(D15,'130-72'!D:E,2,0)) -> #N/A | X15: =IF(D15="(연결)","",VLOOKUP(D15,'150-36-2'!D:E,2,0)) -> #N/A | Y15: =IF(D15="(연결)","",VLOOKUP(D15,'166-144'!D:E,2,0)) -> #N/A | Z15: =IF(D15="(연결)","",VLOOKUP(D15,'187-144-2'!D:E,2,0)) -> #N/A | AA15: =IF(D15="(연결)","",VLOOKUP(D15,'201-36'!D:E,2,0)) -> #N/A | AB15: =IF(D15="(연결)","",VLOOKUP(D15,'201-72'!D:E,2,0)) -> #N/A | AC15: =IF(D15="(연결)","",VLOOKUP(D15,'201-72-2'!D:E,2,0)) -> #N/A | AD15: =IF(D15="(연결)","",VLOOKUP(D15,'134-36'!D:E,2,0)) -> #N/A | AE15: 인천간석사옥/인천종합국사(1층)~500087838775_인천지하철2호선_모래내시장역/[중]남동구청역 지하2층 본선 [HLB_인천간석C3_3440A_만수_터_인천2호선(1500062729.1600209029.1500062762)] | AF15: N | AH15: 기타 | AI15: 기타 | AR15: 인천간석사옥/인천종합국사(1층) | AW15: 500087838775_인천지하철2호선_모래내시장역/[중]남동구청역 지하2층 본선
A16: 1 | B16: 8 | D16: (연결) | E16: 8 | F16: =IF(D16="(연결)","",VLOOKUP(D16,'115-144'!D:E,2,0)) | G16: =IF(D16="(연결)","",VLOOKUP(D16,'(115-288)'!D:E,2,0)) | H16: =IF(D16="(연결)","",VLOOKUP(D16,'44-144'!D:E,2,0)) | I16: =IF(D16="(연결)","",VLOOKUP(D16,'44-144-1'!D:E,2,0)) | J16: =IF(D16="(연결)","",VLOOKUP(D16,'44-288'!D:E,2,0)) | K16: =IF(D16="(연결)","",VLOOKUP(D16,'44-288-1'!D:E,2,0)) | L16: =IF(D16="(연결)","",VLOOKUP(D16,'(44-288)'!D:E,2,0)) | M16: =IF(D16="(연결)","",VLOOKUP(D16,'46-288'!D:E,2,0)) | O16: =IF(D16="(연결)","",VLOOKUP(D16,'46-288-2'!D:E,2,0)) | P16: =IF(D16="(연결)","",VLOOKUP(D16,'(46-288)'!D:E,2,0)) | Q16: =IF(D16="(연결)","",VLOOKUP(D16,'72-72'!D:E,2,0)) | R16: =IF(D16="(연결)","",VLOOKUP(D16,'72-144'!D:E,2,0)) | S16: =IF(D16="(연결)","",VLOOKUP(D16,'73-12'!D:E,2,0)) | T16: =IF(D16="(연결)","",VLOOKUP(D16,'104-12'!D:E,2,0)) | U16: =IF(D16="(연결)","",VLOOKUP(D16,'105-36'!D:E,2,0)) | W16: =IF(D16="(연결)","",VLOOKUP(D16,'130-72'!D:E,2,0)) | X16: =IF(D16="(연결)","",VLOOKUP(D16,'150-36-2'!D:E,2,0)) | Y16: =IF(D16="(연결)","",VLOOKUP(D16,'166-144'!D:E,2,0)) | Z16: =IF(D16="(연결)","",VLOOKUP(D16,'187-144-2'!D:E,2,0)) | AA16: =IF(D16="(연결)","",VLOOKUP(D16,'201-36'!D:E,2,0)) | AC16: =IF(D16="(연결)","",VLOOKUP(D16,'201-72-2'!D:E,2,0)) | AD16: =IF(D16="(연결)","",VLOOKUP(D16,'134-36'!D:E,2,0)) | AE16: 인천종합국사(1층)(북인천분배센터)(뱅크)~[중접완료]8820A631#1 | AF16: N
A17: 1 | B17: 9 | C17: 운영중(OK) | D17: 3060843859 | E17: 9 | F17: =IF(D17="(연결)","",VLOOKUP(D17,'115-144'!D:E,2,0)) -> #N/A | G17: =IF(D17="(연결)","",VLOOKUP(D17,'(115-288)'!D:E,2,0)) -> #N/A | H17: =IF(D17="(연결)","",VLOOKUP(D17,'44-144'!D:E,2,0)) -> #N/A | I17: =IF(D17="(연결)","",VLOOKUP(D17,'44-144-1'!D:E,2,0)) -> #N/A | J17: =IF(D17="(연결)","",VLOOKUP(D17,'44-288'!D:E,2,0)) -> #N/A | K17: =IF(D17="(연결)","",VLOOKUP(D17,'44-288-1'!D:E,2,0)) -> #N/A | L17: =IF(D17="(연결)","",VLOOKUP(D17,'(44-288)'!D:E,2,0)) -> #N/A | M17: =IF(D17="(연결)","",VLOOKUP(D17,'46-288'!D:E,2,0)) -> #N/A | N17: =IF(D17="(연결)","",VLOOKUP(D17,'46-288-1'!D:E,2,0)) -> #N/A | O17: =IF(D17="(연결)","",VLOOKUP(D17,'46-288-2'!D:E,2,0)) -> #N/A | P17: =IF(D17="(연결)","",VLOOKUP(D17,'(46-288)'!D:E,2,0)) -> #N/A | Q17: =IF(D17="(연결)","",VLOOKUP(D17,'72-72'!D:E,2,0)) -> #N/A | R17: =IF(D17="(연결)","",VLOOKUP(D17,'72-144'!D:E,2,0)) -> #N/A | S17: =IF(D17="(연결)","",VLOOKUP(D17,'73-12'!D:E,2,0)) -> #N/A | T17: =IF(D17="(연결)","",VLOOKUP(D17,'104-12'!D:E,2,0)) -> 3 | U17: =IF(D17="(연결)","",VLOOKUP(D17,'105-36'!D:E,2,0)) -> #N/A | V17: =IF(D17="(연결)","",VLOOKUP(D17,'105-72'!D:E,2,0)) -> #N/A | W17: =IF(D17="(연결)","",VLOOKUP(D17,'130-72'!D:E,2,0)) -> #N/A | X17: =IF(D17="(연결)","",VLOOKUP(D17,'150-36-2'!D:E,2,0)) -> #N/A | Y17: =IF(D17="(연결)","",VLOOKUP(D17,'166-144'!D:E,2,0)) -> #N/A | Z17: =IF(D17="(연결)","",VLOOKUP(D17,'187-144-2'!D:E,2,0)) -> #N/A | AA17: =IF(D17="(연결)","",VLOOKUP(D17,'201-36'!D:E,2,0)) -> #N/A | AB17: =IF(D17="(연결)","",VLOOKUP(D17,'201-72'!D:E,2,0)) -> #N/A | AC17: =IF(D17="(연결)","",VLOOKUP(D17,'201-72-2'!D:E,2,0)) -> #N/A | AD17: =IF(D17="(연결)","",VLOOKUP(D17,'134-36'!D:E,2,0)) -> #N/A | AE17: 인천간석사옥/인천종합국사(2층) [INIH]~간석동 우리은행(만수동지점)_500009389712/500208245586/500204869797_만수동금융센터 [간석동 우리은행(만수동지점)_500009389712/500208245586_만수동금융센터_B향] | AF17: N | AI17: 기타 | AR17: 인천간석사옥/인천종합국사(2층) [INIH] | AS17: UTRANS-1664 | AU17: 우리은행 집선#1 | AV17: P11 | AW17: 간석동 우리은행(만수동지점)_500009389712/500208245586/500204869797_만수동금융센터 | AX17: 1646SMC(AC) | AY17: 5WRB-ManSuDongGYC | AZ17: 우리은행_만수동금융센터 | BA17: P2
A18: 1 | B18: 10 | C18: 운영중(OK) | D18: 3060843860 | E18: 10 | F18: =IF(D18="(연결)","",VLOOKUP(D18,'115-144'!D:E,2,0)) -> #N/A | G18: =IF(D18="(연결)","",VLOOKUP(D18,'(115-288)'!D:E,2,0)) -> #N/A | H18: =IF(D18="(연결)","",VLOOKUP(D18,'44-144'!D:E,2,0)) -> #N/A | I18: =IF(D18="(연결)","",VLOOKUP(D18,'44-144-1'!D:E,2,0)) -> #N/A | J18: =IF(D18="(연결)","",VLOOKUP(D18,'44-288'!D:E,2,0)) -> #N/A | K18: =IF(D18="(연결)","",VLOOKUP(D18,'44-288-1'!D:E,2,0)) -> #N/A | L18: =IF(D18="(연결)","",VLOOKUP(D18,'(44-288)'!D:E,2,0)) -> #N/A | M18: =IF(D18="(연결)","",VLOOKUP(D18,'46-288'!D:E,2,0)) -> #N/A | N18: =IF(D18="(연결)","",VLOOKUP(D18,'46-288-1'!D:E,2,0)) -> #N/A | O18: =IF(D18="(연결)","",VLOOKUP(D18,'46-288-2'!D:E,2,0)) -> #N/A | P18: =IF(D18="(연결)","",VLOOKUP(D18,'(46-288)'!D:E,2,0)) -> #N/A | Q18: =IF(D18="(연결)","",VLOOKUP(D18,'72-72'!D:E,2,0)) -> #N/A | R18: =IF(D18="(연결)","",VLOOKUP(D18,'72-144'!D:E,2,0)) -> #N/A | S18: =IF(D18="(연결)","",VLOOKUP(D18,'73-12'!D:E,2,0)) -> #N/A | T18: =IF(D18="(연결)","",VLOOKUP(D18,'104-12'!D:E,2,0)) -> 4 | U18: =IF(D18="(연결)","",VLOOKUP(D18,'105-36'!D:E,2,0)) -> #N/A | V18: =IF(D18="(연결)","",VLOOKUP(D18,'105-72'!D:E,2,0)) -> #N/A | W18: =IF(D18="(연결)","",VLOOKUP(D18,'130-72'!D:E,2,0)) -> #N/A | X18: =IF(D18="(연결)","",VLOOKUP(D18,'150-36-2'!D:E,2,0)) -> #N/A | Y18: =IF(D18="(연결)","",VLOOKUP(D18,'166-144'!D:E,2,0)) -> #N/A | Z18: =IF(D18="(연결)","",VLOOKUP(D18,'187-144-2'!D:E,2,0)) -> #N/A | AA18: =IF(D18="(연결)","",VLOOKUP(D18,'201-36'!D:E,2,0)) -> #N/A | AB18: =IF(D18="(연결)","",VLOOKUP(D18,'201-72'!D:E,2,0)) -> #N/A | AC18: =IF(D18="(연결)","",VLOOKUP(D18,'201-72-2'!D:E,2,0)) -> #N/A | AD18: =IF(D18="(연결)","",VLOOKUP(D18,'134-36'!D:E,2,0)) -> #N/A | AE18: 인천간석사옥/인천종합국사(2층) [INIH]~간석동 우리은행(만수동지점)_500009389712/500208245586/500204869797_만수동금융센터 [간석동 우리은행(만수동지점)_500009389712/500208245586_만수동금융센터_B향] | AF18: N | AI18: 기타 | AR18: 인천간석사옥/인천종합국사(2층) [INIH] | AS18: UTRANS-1664 | AU18: 우리은행 집선#1 | AV18: P11 | AW18: 간석동 우리은행(만수동지점)_500009389712/500208245586/500204869797_만수동금융센터 | AX18: 1646SMC(AC) | AY18: 5WRB-ManSuDongGYC | AZ18: 우리은행_만수동금융센터 | BA18: P2
A19: 1 | B19: 11 | C19: 운영중(OK) | D19: 9842955 | E19: 11 | F19: =IF(D19="(연결)","",VLOOKUP(D19,'115-144'!D:E,2,0)) -> #N/A | G19: =IF(D19="(연결)","",VLOOKUP(D19,'(115-288)'!D:E,2,0)) -> #N/A | H19: =IF(D19="(연결)","",VLOOKUP(D19,'44-144'!D:E,2,0)) -> #N/A | I19: =IF(D19="(연결)","",VLOOKUP(D19,'44-144-1'!D:E,2,0)) -> #N/A | J19: =IF(D19="(연결)","",VLOOKUP(D19,'44-288'!D:E,2,0)) -> 209 | K19: =IF(D19="(연결)","",VLOOKUP(D19,'44-288-1'!D:E,2,0)) -> #N/A | L19: =IF(D19="(연결)","",VLOOKUP(D19,'(44-288)'!D:E,2,0)) -> 45 | M19: =IF(D19="(연결)","",VLOOKUP(D19,'46-288'!D:E,2,0)) -> #N/A | N19: =IF(D19="(연결)","",VLOOKUP(D19,'46-288-1'!D:E,2,0)) -> #N/A | O19: =IF(D19="(연결)","",VLOOKUP(D19,'46-288-2'!D:E,2,0)) -> #N/A | P19: =IF(D19="(연결)","",VLOOKUP(D19,'(46-288)'!D:E,2,0)) -> #N/A | Q19: =IF(D19="(연결)","",VLOOKUP(D19,'72-72'!D:E,2,0)) -> #N/A | R19: =IF(D19="(연결)","",VLOOKUP(D19,'72-144'!D:E,2,0)) -> #N/A | S19: =IF(D19="(연결)","",VLOOKUP(D19,'73-12'!D:E,2,0)) -> #N/A | T19: =IF(D19="(연결)","",VLOOKUP(D19,'104-12'!D:E,2,0)) -> #N/A | U19: =IF(D19="(연결)","",VLOOKUP(D19,'105-36'!D:E,2,0)) -> #N/A | V19: =IF(D19="(연결)","",VLOOKUP(D19,'105-72'!D:E,2,0)) -> #N/A | W19: =IF(D19="(연결)","",VLOOKUP(D19,'130-72'!D:E,2,0)) -> #N/A | X19: =IF(D19="(연결)","",VLOOKUP(D19,'150-36-2'!D:E,2,0)) -> #N/A | Y19: =IF(D19="(연결)","",VLOOKUP(D19,'166-144'!D:E,2,0)) -> #N/A | Z19: =IF(D19="(연결)","",VLOOKUP(D19,'187-144-2'!D:E,2,0)) -> #N/A | AA19: =IF(D19="(연결)","",VLOOKUP(D19,'201-36'!D:E,2,0)) -> #N/A | AB19: =IF(D19="(연결)","",VLOOKUP(D19,'201-72'!D:E,2,0)) -> #N/A | AC19: =IF(D19="(연결)","",VLOOKUP(D19,'201-72-2'!D:E,2,0)) -> #N/A | AD19: =IF(D19="(연결)","",VLOOKUP(D19,'134-36'!D:E,2,0)) -> #N/A | AE19: 인천간석사옥/인천종합국사(1층)~500087838775_인천지하철2호선_모래내시장역/[중]남동구청역 지하2층 본선 [HLB_인천간석C4_3210A_남동구청_터_인천2호선(1500062732.1600209032.1500062765)] | AF19: N | AH19: 기타 | AI19: 기타 | AR19: 인천간석사옥/인천종합국사(1층) | AW19: 500087838775_인천지하철2호선_모래내시장역/[중]남동구청역 지하2층 본선
A20: 1 | B20: 12 | C20: 운영중(OK) | D20: 9842956 | E20: 12 | F20: =IF(D20="(연결)","",VLOOKUP(D20,'115-144'!D:E,2,0)) -> #N/A | G20: =IF(D20="(연결)","",VLOOKUP(D20,'(115-288)'!D:E,2,0)) -> #N/A | H20: =IF(D20="(연결)","",VLOOKUP(D20,'44-144'!D:E,2,0)) -> #N/A | I20: =IF(D20="(연결)","",VLOOKUP(D20,'44-144-1'!D:E,2,0)) -> #N/A | J20: =IF(D20="(연결)","",VLOOKUP(D20,'44-288'!D:E,2,0)) -> 210 | K20: =IF(D20="(연결)","",VLOOKUP(D20,'44-288-1'!D:E,2,0)) -> #N/A | L20: =IF(D20="(연결)","",VLOOKUP(D20,'(44-288)'!D:E,2,0)) -> 46 | M20: =IF(D20="(연결)","",VLOOKUP(D20,'46-288'!D:E,2,0)) -> #N/A | N20: =IF(D20="(연결)","",VLOOKUP(D20,'46-288-1'!D:E,2,0)) -> #N/A | O20: =IF(D20="(연결)","",VLOOKUP(D20,'46-288-2'!D:E,2,0)) -> #N/A | P20: =IF(D20="(연결)","",VLOOKUP(D20,'(46-288)'!D:E,2,0)) -> #N/A | Q20: =IF(D20="(연결)","",VLOOKUP(D20,'72-72'!D:E,2,0)) -> #N/A | R20: =IF(D20="(연결)","",VLOOKUP(D20,'72-144'!D:E,2,0)) -> #N/A | S20: =IF(D20="(연결)","",VLOOKUP(D20,'73-12'!D:E,2,0)) -> #N/A | T20: =IF(D20="(연결)","",VLOOKUP(D20,'104-12'!D:E,2,0)) -> #N/A | U20: =IF(D20="(연결)","",VLOOKUP(D20,'105-36'!D:E,2,0)) -> #N/A | V20: =IF(D20="(연결)","",VLOOKUP(D20,'105-72'!D:E,2,0)) -> #N/A | W20: =IF(D20="(연결)","",VLOOKUP(D20,'130-72'!D:E,2,0)) -> #N/A | X20: =IF(D20="(연결)","",VLOOKUP(D20,'150-36-2'!D:E,2,0)) -> #N/A | Y20: =IF(D20="(연결)","",VLOOKUP(D20,'166-144'!D:E,2,0)) -> #N/A | Z20: =IF(D20="(연결)","",VLOOKUP(D20,'187-144-2'!D:E,2,0)) -> #N/A | AA20: =IF(D20="(연결)","",VLOOKUP(D20,'201-36'!D:E,2,0)) -> #N/A | AB20: =IF(D20="(연결)","",VLOOKUP(D20,'201-72'!D:E,2,0)) -> #N/A | AC20: =IF(D20="(연결)","",VLOOKUP(D20,'201-72-2'!D:E,2,0)) -> #N/A | AD20: =IF(D20="(연결)","",VLOOKUP(D20,'134-36'!D:E,2,0)) -> #N/A | AE20: 인천간석사옥/인천종합국사(1층)~500087838775_인천지하철2호선_모래내시장역/[중]남동구청역 지하2층 본선 [HLB_인천간석C4_3200A_남동구청_터_인천2호선(1500062711.1600209033.1500062764)] | AF20: N | AH20: 기타 | AI20: 기타 | AR20: 인천간석사옥/인천종합국사(1층) | AW20: 500087838775_인천지하철2호선_모래내시장역/[중]남동구청역 지하2층 본선
A21: Unit#2 | F21: =IF(D21="(연결)","",VLOOKUP(D21,'115-144'!D:E,2,0)) | G21: =IF(D21="(연결)","",VLOOKUP(D21,'(115-288)'!D:E,2,0)) | H21: =IF(D21="(연결)","",VLOOKUP(D21,'44-144'!D:E,2,0)) | I21: =IF(D21="(연결)","",VLOOKUP(D21,'44-144-1'!D:E,2,0)) | J21: =IF(D21="(연결)","",VLOOKUP(D21,'44-288'!D:E,2,0)) | K21: =IF(D21="(연결)","",VLOOKUP(D21,'44-288-1'!D:E,2,0)) | L21: =IF(D21="(연결)","",VLOOKUP(D21,'(44-288)'!D:E,2,0)) | M21: =IF(D21="(연결)","",VLOOKUP(D21,'46-288'!D:E,2,0)) | O21: =IF(D21="(연결)","",VLOOKUP(D21,'46-288-2'!D:E,2,0)) | P21: =IF(D21="(연결)","",VLOOKUP(D21,'(46-288)'!D:E,2,0)) | Q21: =IF(D21="(연결)","",VLOOKUP(D21,'72-72'!D:E,2,0)) | R21: =IF(D21="(연결)","",VLOOKUP(D21,'72-144'!D:E,2,0)) | S21: =IF(D21="(연결)","",VLOOKUP(D21,'73-12'!D:E,2,0)) | T21: =IF(D21="(연결)","",VLOOKUP(D21,'104-12'!D:E,2,0)) | U21: =IF(D21="(연결)","",VLOOKUP(D21,'105-36'!D:E,2,0)) | W21: =IF(D21="(연결)","",VLOOKUP(D21,'130-72'!D:E,2,0)) | X21: =IF(D21="(연결)","",VLOOKUP(D21,'150-36-2'!D:E,2,0)) | Y21: =IF(D21="(연결)","",VLOOKUP(D21,'166-144'!D:E,2,0)) | Z21: =IF(D21="(연결)","",VLOOKUP(D21,'187-144-2'!D:E,2,0)) | AA21: =IF(D21="(연결)","",VLOOKUP(D21,'201-36'!D:E,2,0)) | AC21: =IF(D21="(연결)","",VLOOKUP(D21,'201-72-2'!D:E,2,0)) | AD21: =IF(D21="(연결)","",VLOOKUP(D21,'134-36'!D:E,2,0))
A22: 2 | B22: 13 | D22: (연결) | E22: 13 | F22: =IF(D22="(연결)","",VLOOKUP(D22,'115-144'!D:E,2,0)) | G22: =IF(D22="(연결)","",VLOOKUP(D22,'(115-288)'!D:E,2,0)) | H22: =IF(D22="(연결)","",VLOOKUP(D22,'44-144'!D:E,2,0)) | I22: =IF(D22="(연결)","",VLOOKUP(D22,'44-144-1'!D:E,2,0)) | J22: =IF(D22="(연결)","",VLOOKUP(D22,'44-288'!D:E,2,0)) | K22: =IF(D22="(연결)","",VLOOKUP(D22,'44-288-1'!D:E,2,0)) | L22: =IF(D22="(연결)","",VLOOKUP(D22,'(44-288)'!D:E,2,0)) | M22: =IF(D22="(연결)","",VLOOKUP(D22,'46-288'!D:E,2,0)) | O22: =IF(D22="(연결)","",VLOOKUP(D22,'46-288-2'!D:E,2,0)) | P22: =IF(D22="(연결)","",VLOOKUP(D22,'(46-288)'!D:E,2,0)) | Q22: =IF(D22="(연결)","",VLOOKUP(D22,'72-72'!D:E,2,0)) | R22: =IF(D22="(연결)","",VLOOKUP(D22,'72-144'!D:E,2,0)) | S22: =IF(D22="(연결)","",VLOOKUP(D22,'73-12'!D:E,2,0)) | T22: =IF(D22="(연결)","",VLOOKUP(D22,'104-12'!D:E,2,0)) | U22: =IF(D22="(연결)","",VLOOKUP(D22,'105-36'!D:E,2,0)) | W22: =IF(D22="(연결)","",VLOOKUP(D22,'130-72'!D:E,2,0)) | X22: =IF(D22="(연결)","",VLOOKUP(D22,'150-36-2'!D:E,2,0)) | Y22: =IF(D22="(연결)","",VLOOKUP(D22,'166-144'!D:E,2,0)) | Z22: =IF(D22="(연결)","",VLOOKUP(D22,'187-144-2'!D:E,2,0)) | AA22: =IF(D22="(연결)","",VLOOKUP(D22,'201-36'!D:E,2,0)) | AC22: =IF(D22="(연결)","",VLOOKUP(D22,'201-72-2'!D:E,2,0)) | AD22: =IF(D22="(연결)","",VLOOKUP(D22,'134-36'!D:E,2,0)) | AE22: ~ | AF22: N
A23: 2 | B23: 14 | D23: (연결) | E23: 14 | F23: =IF(D23="(연결)","",VLOOKUP(D23,'115-144'!D:E,2,0)) | G23: =IF(D23="(연결)","",VLOOKUP(D23,'(115-288)'!D:E,2,0)) | H23: =IF(D23="(연결)","",VLOOKUP(D23,'44-144'!D:E,2,0)) | I23: =IF(D23="(연결)","",VLOOKUP(D23,'44-144-1'!D:E,2,0)) | J23: =IF(D23="(연결)","",VLOOKUP(D23,'44-288'!D:E,2,0)) | K23: =IF(D23="(연결)","",VLOOKUP(D23,'44-288-1'!D:E,2,0)) | L23: =IF(D23="(연결)","",VLOOKUP(D23,'(44-288)'!D:E,2,0)) | M23: =IF(D23="(연결)","",VLOOKUP(D23,'46-288'!D:E,2,0)) | O23: =IF(D23="(연결)","",VLOOKUP(D23,'46-288-2'!D:E,2,0)) | P23: =IF(D23="(연결)","",VLOOKUP(D23,'(46-288)'!D:E,2,0)) | Q23: =IF(D23="(연결)","",VLOOKUP(D23,'72-72'!D:E,2,0)) | R23: =IF(D23="(연결)","",VLOOKUP(D23,'72-144'!D:E,2,0)) | S23: =IF(D23="(연결)","",VLOOKUP(D23,'73-12'!D:E,2,0)) | T23: =IF(D23="(연결)","",VLOOKUP(D23,'104-12'!D:E,2,0)) | U23: =IF(D23="(연결)","",VLOOKUP(D23,'105-36'!D:E,2,0)) | W23: =IF(D23="(연결)","",VLOOKUP(D23,'130-72'!D:E,2,0)) | X23: =IF(D23="(연결)","",VLOOKUP(D23,'150-36-2'!D:E,2,0)) | Y23: =IF(D23="(연결)","",VLOOKUP(D23,'166-144'!D:E,2,0)) | Z23: =IF(D23="(연결)","",VLOOKUP(D23,'187-144-2'!D:E,2,0)) | AA23: =IF(D23="(연결)","",VLOOKUP(D23,'201-36'!D:E,2,0)) | AC23: =IF(D23="(연결)","",VLOOKUP(D23,'201-72-2'!D:E,2,0)) | AD23: =IF(D23="(연결)","",VLOOKUP(D23,'134-36'!D:E,2,0)) | AE23: ~ | AF23: N
A24: 2 | B24: 15 | C24: 운영중(OK) | D24: 9842957 | E24: 15 | F24: =IF(D24="(연결)","",VLOOKUP(D24,'115-144'!D:E,2,0)) -> #N/A | G24: =IF(D24="(연결)","",VLOOKUP(D24,'(115-288)'!D:E,2,0)) -> #N/A | H24: =IF(D24="(연결)","",VLOOKUP(D24,'44-144'!D:E,2,0)) -> #N/A | I24: =IF(D24="(연결)","",VLOOKUP(D24,'44-144-1'!D:E,2,0)) -> #N/A | J24: =IF(D24="(연결)","",VLOOKUP(D24,'44-288'!D:E,2,0)) -> 211 | K24: =IF(D24="(연결)","",VLOOKUP(D24,'44-288-1'!D:E,2,0)) -> #N/A | L24: =IF(D24="(연결)","",VLOOKUP(D24,'(44-288)'!D:E,2,0)) -> 47 | M24: =IF(D24="(연결)","",VLOOKUP(D24,'46-288'!D:E,2,0)) -> #N/A | N24: =IF(D24="(연결)","",VLOOKUP(D24,'46-288-1'!D:E,2,0)) -> #N/A | O24: =IF(D24="(연결)","",VLOOKUP(D24,'46-288-2'!D:E,2,0)) -> #N/A | P24: =IF(D24="(연결)","",VLOOKUP(D24,'(46-288)'!D:E,2,0)) -> #N/A | Q24: =IF(D24="(연결)","",VLOOKUP(D24,'72-72'!D:E,2,0)) -> #N/A | R24: =IF(D24="(연결)","",VLOOKUP(D24,'72-144'!D:E,2,0)) -> #N/A | S24: =IF(D24="(연결)","",VLOOKUP(D24,'73-12'!D:E,2,0)) -> #N/A | T24: =IF(D24="(연결)","",VLOOKUP(D24,'104-12'!D:E,2,0)) -> #N/A | U24: =IF(D24="(연결)","",VLOOKUP(D24,'105-36'!D:E,2,0)) -> #N/A | V24: =IF(D24="(연결)","",VLOOKUP(D24,'105-72'!D:E,2,0)) -> #N/A | W24: =IF(D24="(연결)","",VLOOKUP(D24,'130-72'!D:E,2,0)) -> #N/A | X24: =IF(D24="(연결)","",VLOOKUP(D24,'150-36-2'!D:E,2,0)) -> #N/A | Y24: =IF(D24="(연결)","",VLOOKUP(D24,'166-144'!D:E,2,0)) -> #N/A | Z24: =IF(D24="(연결)","",VLOOKUP(D24,'187-144-2'!D:E,2,0)) -> #N/A | AA24: =IF(D24="(연결)","",VLOOKUP(D24,'201-36'!D:E,2,0)) -> #N/A | AB24: =IF(D24="(연결)","",VLOOKUP(D24,'201-72'!D:E,2,0)) -> #N/A | AC24: =IF(D24="(연결)","",VLOOKUP(D24,'201-72-2'!D:E,2,0)) -> #N/A | AD24: =IF(D24="(연결)","",VLOOKUP(D24,'134-36'!D:E,2,0)) -> #N/A | AE24: 인천간석사옥/인천종합국사(1층)~500087838775_인천지하철2호선_모래내시장역/[중]남동구청역 지하2층 본선 [HLB_인천간석C4_3330A_남동구청_승_인천2호선(1500062733.1600209034.1500062766)] | AF24: N | AH24: 기타 | AI24: 기타 | AR24: 인천간석사옥/인천종합국사(1층) | AW24: 500087838775_인천지하철2호선_모래내시장역/[중]남동구청역 지하2층 본선
A25: 2 | B25: 16 | C25: 운영중(OK) | D25: 9842970 | E25: 16 | F25: =IF(D25="(연결)","",VLOOKUP(D25,'115-144'!D:E,2,0)) -> #N/A | G25: =IF(D25="(연결)","",VLOOKUP(D25,'(115-288)'!D:E,2,0)) -> #N/A | H25: =IF(D25="(연결)","",VLOOKUP(D25,'44-144'!D:E,2,0)) -> #N/A | I25: =IF(D25="(연결)","",VLOOKUP(D25,'44-144-1'!D:E,2,0)) -> #N/A | J25: =IF(D25="(연결)","",VLOOKUP(D25,'44-288'!D:E,2,0)) -> 212 | K25: =IF(D25="(연결)","",VLOOKUP(D25,'44-288-1'!D:E,2,0)) -> #N/A | L25: =IF(D25="(연결)","",VLOOKUP(D25,'(44-288)'!D:E,2,0)) -> 48 | M25: =IF(D25="(연결)","",VLOOKUP(D25,'46-288'!D:E,2,0)) -> #N/A | N25: =IF(D25="(연결)","",VLOOKUP(D25,'46-288-1'!D:E,2,0)) -> #N/A | O25: =IF(D25="(연결)","",VLOOKUP(D25,'46-288-2'!D:E,2,0)) -> #N/A | P25: =IF(D25="(연결)","",VLOOKUP(D25,'(46-288)'!D:E,2,0)) -> #N/A | Q25: =IF(D25="(연결)","",VLOOKUP(D25,'72-72'!D:E,2,0)) -> #N/A | R25: =IF(D25="(연결)","",VLOOKUP(D25,'72-144'!D:E,2,0)) -> #N/A | S25: =IF(D25="(연결)","",VLOOKUP(D25,'73-12'!D:E,2,0)) -> #N/A | T25: =IF(D25="(연결)","",VLOOKUP(D25,'104-12'!D:E,2,0)) -> #N/A | U25: =IF(D25="(연결)","",VLOOKUP(D25,'105-36'!D:E,2,0)) -> #N/A | V25: =IF(D25="(연결)","",VLOOKUP(D25,'105-72'!D:E,2,0)) -> #N/A | W25: =IF(D25="(연결)","",VLOOKUP(D25,'130-72'!D:E,2,0)) -> #N/A | X25: =IF(D25="(연결)","",VLOOKUP(D25,'150-36-2'!D:E,2,0)) -> #N/A | Y25: =IF(D25="(연결)","",VLOOKUP(D25,'166-144'!D:E,2,0)) -> #N/A | Z25: =IF(D25="(연결)","",VLOOKUP(D25,'187-144-2'!D:E,2,0)) -> #N/A | AA25: =IF(D25="(연결)","",VLOOKUP(D25,'201-36'!D:E,2,0)) -> #N/A | AB25: =IF(D25="(연결)","",VLOOKUP(D25,'201-72'!D:E,2,0)) -> #N/A | AC25: =IF(D25="(연결)","",VLOOKUP(D25,'201-72-2'!D:E,2,0)) -> #N/A | AD25: =IF(D25="(연결)","",VLOOKUP(D25,'134-36'!D:E,2,0)) -> #N/A | AE25: 인천간석사옥/인천종합국사(1층)~500087838775_인천지하철2호선_모래내시장역/[중]남동구청역 지하2층 본선 [HLB_인천간석C4_3320A_남동구청_대_인천2호선(1500062731.1600209031.1500062744)] | AF25: N | AH25: 기타 | AI25: 기타 | AR25: 인천간석사옥/인천종합국사(1층) | AW25: 500087838775_인천지하철2호선_모래내시장역/[중]남동구청역 지하2층 본선
A26: 2 | B26: 17 | D26: (연결) | E26: 17 | F26: =IF(D26="(연결)","",VLOOKUP(D26,'115-144'!D:E,2,0)) | G26: =IF(D26="(연결)","",VLOOKUP(D26,'(115-288)'!D:E,2,0)) | H26: =IF(D26="(연결)","",VLOOKUP(D26,'44-144'!D:E,2,0)) | I26: =IF(D26="(연결)","",VLOOKUP(D26,'44-144-1'!D:E,2,0)) | J26: =IF(D26="(연결)","",VLOOKUP(D26,'44-288'!D:E,2,0)) | K26: =IF(D26="(연결)","",VLOOKUP(D26,'44-288-1'!D:E,2,0)) | L26: =IF(D26="(연결)","",VLOOKUP(D26,'(44-288)'!D:E,2,0)) | M26: =IF(D26="(연결)","",VLOOKUP(D26,'46-288'!D:E,2,0)) | O26: =IF(D26="(연결)","",VLOOKUP(D26,'46-288-2'!D:E,2,0)) | P26: =IF(D26="(연결)","",VLOOKUP(D26,'(46-288)'!D:E,2,0)) | Q26: =IF(D26="(연결)","",VLOOKUP(D26,'72-72'!D:E,2,0)) | R26: =IF(D26="(연결)","",VLOOKUP(D26,'72-144'!D:E,2,0)) | S26: =IF(D26="(연결)","",VLOOKUP(D26,'73-12'!D:E,2,0)) | T26: =IF(D26="(연결)","",VLOOKUP(D26,'104-12'!D:E,2,0)) | U26: =IF(D26="(연결)","",VLOOKUP(D26,'105-36'!D:E,2,0)) | W26: =IF(D26="(연결)","",VLOOKUP(D26,'130-72'!D:E,2,0)) | X26: =IF(D26="(연결)","",VLOOKUP(D26,'150-36-2'!D:E,2,0)) | Y26: =IF(D26="(연결)","",VLOOKUP(D26,'166-144'!D:E,2,0)) | Z26: =IF(D26="(연결)","",VLOOKUP(D26,'187-144-2'!D:E,2,0)) | AA26: =IF(D26="(연결)","",VLOOKUP(D26,'201-36'!D:E,2,0)) | AC26: =IF(D26="(연결)","",VLOOKUP(D26,'201-72-2'!D:E,2,0)) | AD26: =IF(D26="(연결)","",VLOOKUP(D26,'134-36'!D:E,2,0)) | AE26: ~ | AF26: N
A27: 2 | B27: 18 | D27: (연결) | E27: 18 | F27: =IF(D27="(연결)","",VLOOKUP(D27,'115-144'!D:E,2,0)) | G27: =IF(D27="(연결)","",VLOOKUP(D27,'(115-288)'!D:E,2,0)) | H27: =IF(D27="(연결)","",VLOOKUP(D27,'44-144'!D:E,2,0)) | I27: =IF(D27="(연결)","",VLOOKUP(D27,'44-144-1'!D:E,2,0)) | J27: =IF(D27="(연결)","",VLOOKUP(D27,'44-288'!D:E,2,0)) | K27: =IF(D27="(연결)","",VLOOKUP(D27,'44-288-1'!D:E,2,0)) | L27: =IF(D27="(연결)","",VLOOKUP(D27,'(44-288)'!D:E,2,0)) | M27: =IF(D27="(연결)","",VLOOKUP(D27,'46-288'!D:E,2,0)) | O27: =IF(D27="(연결)","",VLOOKUP(D27,'46-288-2'!D:E,2,0)) | P27: =IF(D27="(연결)","",VLOOKUP(D27,'(46-288)'!D:E,2,0)) | Q27: =IF(D27="(연결)","",VLOOKUP(D27,'72-72'!D:E,2,0)) | R27: =IF(D27="(연결)","",VLOOKUP(D27,'72-144'!D:E,2,0)) | S27: =IF(D27="(연결)","",VLOOKUP(D27,'73-12'!D:E,2,0)) | T27: =IF(D27="(연결)","",VLOOKUP(D27,'104-12'!D:E,2,0)) | U27: =IF(D27="(연결)","",VLOOKUP(D27,'105-36'!D:E,2,0)) | W27: =IF(D27="(연결)","",VLOOKUP(D27,'130-72'!D:E,2,0)) | X27: =IF(D27="(연결)","",VLOOKUP(D27,'150-36-2'!D:E,2,0)) | Y27: =IF(D27="(연결)","",VLOOKUP(D27,'166-144'!D:E,2,0)) | Z27: =IF(D27="(연결)","",VLOOKUP(D27,'187-144-2'!D:E,2,0)) | AA27: =IF(D27="(연결)","",VLOOKUP(D27,'201-36'!D:E,2,0)) | AC27: =IF(D27="(연결)","",VLOOKUP(D27,'201-72-2'!D:E,2,0)) | AD27: =IF(D27="(연결)","",VLOOKUP(D27,'134-36'!D:E,2,0)) | AE27: ~ | AF27: N
A28: 2 | B28: 19 | C28: 운영중(OK) | D28: 3061840392 | E28: 19 | F28: =IF(D28="(연결)","",VLOOKUP(D28,'115-144'!D:E,2,0)) -> #N/A | G28: =IF(D28="(연결)","",VLOOKUP(D28,'(115-288)'!D:E,2,0)) -> #N/A | H28: =IF(D28="(연결)","",VLOOKUP(D28,'44-144'!D:E,2,0)) -> 71 | I28: =IF(D28="(연결)","",VLOOKUP(D28,'44-144-1'!D:E,2,0)) -> #N/A | J28: =IF(D28="(연결)","",VLOOKUP(D28,'44-288'!D:E,2,0)) -> #N/A | K28: =IF(D28="(연결)","",VLOOKUP(D28,'44-288-1'!D:E,2,0)) -> #N/A | L28: =IF(D28="(연결)","",VLOOKUP(D28,'(44-288)'!D:E,2,0)) -> 11 | M28: =IF(D28="(연결)","",VLOOKUP(D28,'46-288'!D:E,2,0)) -> #N/A | N28: =IF(D28="(연결)","",VLOOKUP(D28,'46-288-1'!D:E,2,0)) -> #N/A | O28: =IF(D28="(연결)","",VLOOKUP(D28,'46-288-2'!D:E,2,0)) -> #N/A | P28: =IF(D28="(연결)","",VLOOKUP(D28,'(46-288)'!D:E,2,0)) -> #N/A | Q28: =IF(D28="(연결)","",VLOOKUP(D28,'72-72'!D:E,2,0)) -> #N/A | R28: =IF(D28="(연결)","",VLOOKUP(D28,'72-144'!D:E,2,0)) -> #N/A | S28: =IF(D28="(연결)","",VLOOKUP(D28,'73-12'!D:E,2,0)) -> #N/A | T28: =IF(D28="(연결)","",VLOOKUP(D28,'104-12'!D:E,2,0)) -> #N/A | U28: =IF(D28="(연결)","",VLOOKUP(D28,'105-36'!D:E,2,0)) -> #N/A | V28: =IF(D28="(연결)","",VLOOKUP(D28,'105-72'!D:E,2,0)) -> #N/A | W28: =IF(D28="(연결)","",VLOOKUP(D28,'130-72'!D:E,2,0)) -> #N/A | X28: =IF(D28="(연결)","",VLOOKUP(D28,'150-36-2'!D:E,2,0)) -> #N/A | Y28: =IF(D28="(연결)","",VLOOKUP(D28,'166-144'!D:E,2,0)) -> #N/A | Z28: =IF(D28="(연결)","",VLOOKUP(D28,'187-144-2'!D:E,2,0)) -> #N/A | AA28: =IF(D28="(연결)","",VLOOKUP(D28,'201-36'!D:E,2,0)) -> #N/A | AB28: =IF(D28="(연결)","",VLOOKUP(D28,'201-72'!D:E,2,0)) -> #N/A | AC28: =IF(D28="(연결)","",VLOOKUP(D28,'201-72-2'!D:E,2,0)) -> #N/A | AD28: =IF(D28="(연결)","",VLOOKUP(D28,'134-36'!D:E,2,0)) -> #N/A | AE28: 인천간석사옥/인천종합국사(1층)~500104297707/500252399656_인천발달장애인훈련센터 [[PTN][95INIHCA51 S.1-P2 ~ 95KEADBD_INC S.1-P1] [500252399656_인천발달장애인훈련센터]] | AF28: N | AI28: 기타 | AR28: 인천간석사옥/인천종합국사(1층) | AS28: UTRANS-7320 | AT28: 95INIHCA51 | AU28: 95INIHCA51 | AV28: P2 | AW28: 500104297707/500252399656_인천발달장애인훈련센터 | AX28: UTRANS-7400C2 | AY28: 95KEADBD_INC | AZ28: 95KEADBD_INC | BA28: P1
